Workbook

Sheet Hierarchy
A1: DepartmentCode | B1: DepartmentName | C1: SectionCode | D1: SectionName | E1: SubSectionCode | F1: SubSectionName | G1: BudgetMargin | H1: TargetMargin | I1: MinimumMargin
A2: 6 | B2: Brands | C2: 100 | D2: Gerry Weber | E2: 1 | F2: Blouses | G2: 40 | H2: 50 | I2: 40
A3: 6 | B3: Brands | C3: 100 | D3: Gerry Weber | E3: 2 | F3: Tops | G3: 40 | H3: 50 | I3: 40
A4: 6 | B4: Brands | C4: 100 | D4: Gerry Weber | E4: 3 | F4: Knitwear | G4: 40 | H4: 50 | I4: 40
A5: 6 | B5: Brands | C5: 100 | D5: Gerry Weber | E5: 4 | F5: Dresses | G5: 40 | H5: 50 | I5: 40
A6: 6 | B6: Brands | C6: 100 | D6: Gerry Weber | E6: 5 | F6: Skirts | G6: 40 | H6: 50 | I6: 40
A7: 6 | B7: Brands | C7: 100 | D7: Gerry Weber | E7: 6 | F7: Trousers | G7: 40 | H7: 50 | I7: 40
A8: 6 | B8: Brands | C8: 100 | D8: Gerry Weber | E8: 7 | F8: Jackets | G8: 40 | H8: 50 | I8: 40
A9: 6 | B9: Brands | C9: 100 | D9: Gerry Weber | E9: 8 | F9: Accessories | G9: 40 | H9: 50 | I9: 40
A10: 6 | B10: Brands | C10: 103 | D10: Olsen | E10: 1 | F10: Blouses | G10: 40 | H10: 50 | I10: 40
A11: 6 | B11: Brands | C11: 103 | D11: Olsen | E11: 2 | F11: Tops | G11: 40 | H11: 50 | I11: 40
A12: 6 | B12: Brands | C12: 103 | D12: Olsen | E12: 3 | F12: Knitwear | G12: 40 | H12: 50 | I12: 40
A13: 6 | B13: Brands | C13: 103 | D13: Olsen | E13: 4 | F13: Dresses | G13: 40 | H13: 50 | I13: 40
... A151: 6 | B151: Brands | C151: 146 | D151: Laura Ashley | E151: 6 | F151: Trousers | G151: 40 | H151: 50 | I151: 40

Sheet Sheet1
A1: DepartmentCode | B1: DepartmentName | C1: SectionCode | D1: SectionName | E1: SubSectionCode | F1: SubSectionName | G1: BudgetMargin | H1: TargetMargin | I1: MinimumMargin | L1: Branch Code | M1: Name
A2: 1 | B2: Accessories | C2: 1 | D2: Hosiery | E2: 100 | F2: Special Hosiery | G2: 40 | H2: 50 | I2: 40 | L2: 1 | M2: Edinburgh
A3: 1 | B3: Accessories | C3: 1 | D3: Hosiery | E3: 101 | F3: Gentle Grip Socks | G3: 40 | H3: 50 | I3: 40 | L3: 2 | M3: North Berwich
A4: 1 | B4: Accessories | C4: 1 | D4: Hosiery | E4: 999 | F4: No Type | G4: 40 | H4: 50 | I4: 40 | L4: 3 | M4: Falkirk
A5: 1 | B5: Accessories | C5: 2 | D5: Handbags | E5: 120 | F5: Value Bags | G5: 40 | H5: 50 | I5: 40 | L5: 4 | M5: Helensburgh
A6: 1 | B6: Accessories | C6: 2 | D6: Handbags | E6: 121 | F6: Fashion Bags | G6: 40 | H6: 50 | I6: 40 | L6: 5 | M6: Kirkcaldy
A7: 1 | B7: Accessories | C7: 2 | D7: Handbags | E7: 122 | F7: Leather Bags | G7: 40 | H7: 50 | I7: 40 | L7: 6 | M7: Peebles
A8: 1 | B8: Accessories | C8: 2 | D8: Handbags | E8: 123 | F8: Evening Bags | G8: 40 | H8: 50 | I8: 40 | L8: 8 | M8: Perth
A9: 1 | B9: Accessories | C9: 2 | D9: Handbags | E9: 124 | F9: Travel Bags | G9: 40 | H9: 50 | I9: 40 | L9: 9 | M9: Largs
A10: 1 | B10: Accessories | C10: 2 | D10: Handbags | E10: 126 | F10: Sp Bags | G10: 40 | H10: 50 | I10: 40 | L10: 11 | M10: Dundee
A11: 1 | B11: Accessories | C11: 2 | D11: Handbags | E11: 999 | F11: No Type | G11: 40 | H11: 50 | I11: 40 | L11: 12 | M11: Castle Douglas
A12: 1 | B12: Accessories | C12: 3 | D12: Millinery | E12: 130 | F12: Occasionwear | G12: 40 | H12: 50 | I12: 40 | L12: 13 | M12: Ballater
A13: 1 | B13: Accessories | C13: 3 | D13: Millinery | E13: 131 | F13: Every Day | G13: 40 | H13: 50 | I13: 40 | L13: 15 | M13: Hamilton
... A15: 1 | B15: Accessories | C15: 4 | D15: Isotoner | E15: 140 | F15: Gloves | G15: 40 | H15: 50 | I15: 40 | L15: 990 | M15: Online
A16: 1 | B16: Accessories | C16: 4 | D16: Isotoner | E16: 141 | F16: Slippers | G16: 40 | H16: 50 | I16: 40
A17: 1 | B17: Accessories | C17: 5 | D17: Gifts | E17: 999 | F17: No Type | G17: 40 | H17: 50 | I17: 40
A18: 1 | B18: Accessories | C18: 8 | D18: Jewellery | E18: 195 | F18: Jewellery | G18: 40 | H18: 50 | I18: 40
A19: 1 | B19: Accessories | C19: 8 | D19: Jewellery | E19: 611 | F19: Gadgets | G19: 40 | H19: 50 | I19: 40
A20: 1 | B20: Accessories | C20: 9 | D20: Accessories | E20: 190 | F20: Umbrellas | G20: 40 | H20: 50 | I20: 40
A21: 1 | B21: Accessories | C21: 9 | D21: Accessories | E21: 191 | F21: Scarves | G21: 40 | H21: 50 | I21: 40
A22: 1 | B22: Accessories | C22: 9 | D22: Accessories | E22: 192 | F22: Small Leathers | G22: 40 | H22: 50 | I22: 40
A23: 1 | B23: Accessories | C23: 9 | D23: Accessories | E23: 193 | F23: Gloves | G23: 40 | H23: 50 | I23: 40
A24: 1 | B24: Accessories | C24: 9 | D24: Accessories | E24: 194 | F24: Miscellaneous | G24: 40 | H24: 50 | I24: 40
A25: 2 | B25: Underwear | C25: 22 | D25: Swimwear | E25: 999 | F25: No Type | G25: 40 | H25: 50 | I25: 40
A26: 2 | B26: Underwear | C26: 23 | D26: Nightwear | E26: 999 | F26: No Type | G26: 40 | H26: 50 | I26: 40
A27: 2 | B27: Underwear | C27: 24 | D27: Bras | E27: 200 | F27: Non Wired | G27: 40 | H27: 50 | I27: 40
... A483: 999 | B483: Concessions | C483: 752 | D483: Sock Shop Kids | E483: 999 | F483: No Type | G483: 40 | H483: 50 | I483: 40
A484: 998 | B484: Dump Code | G484: 40 | H484: 50 | I484: 40

Sheet Main
H1: Branch Code | I1: Values
H2: 1 | I2: 1 | J2: 1 | K2: 1 | L2: 1 | M2: 1 | N2: 2 | O2: 2 | P2: 2 | Q2: 2 | R2: 2 | S2: 2 | T2: 3 | U2: 3 | V2: 3 | W2: 3 | X2: 3 | Y2: 3 | Z2: 4 | AA2: 4 | AB2: 4 | AC2: 4 | AD2: 4 | AE2: 4 | AF2: 5 | AG2: 5 | AH2: 5 | AI2: 5 | AJ2: 5 | AK2: 5 | AL2: 6 | AM2: 6 | AN2: 6 | AO2: 6 | AP2: 6 | AQ2: 6 | AR2: 8 | AS2: 8 | AT2: 8 | AU2: 8 | AV2: 8 | AW2: 8 | AX2: 9 | AY2: 9 | AZ2: 9 | BA2: 9 | BB2: 9 | BC2: 9 | BD2: 11 | BE2: 11 | BF2: 11 | BG2: 11 | BH2: 11 | BI2: 11 | BJ2: 12 | BK2: 12 | BL2: 12 | BM2: 12 | BN2: 12 | BO2: 12 | BP2: 13 | BQ2: 13 | BR2: 13 | BS2: 13 | BT2: 13 | BU2: 13 | BV2: 15 | BW2: 15 | BX2: 15 | BY2: 15 | BZ2: 15 | CA2: 15 | CB2: 16 | CC2: 16 | CD2: 16 | CE2: 16 | CF2: 16 | CG2: 16 | CH2: 90 | CI2: 90 | CJ2: 90 | CK2: 90 | CL2: 90 | CM2: 90 | CN2: 990 | CO2: 990 | CP2: 990 | CQ2: 990 | CR2: 990 | CS2: 990 | CT2: Total Sales | CU2: Total Physical Qty | CV2: Total On Order | CW2: Total Sell-Through | CX2: Total Weeks Cover | CY2: Total Cost of Stock
A3: DepartmentName | B3: SectionName | C3: SupplierName | D3: StyleCode | E3: Description | F3: RangeDetail1 | G3: Unit Selling Price | H3: Sales | I3: Physical Qty | J3: On Order | K3: Sell-Through | L3: Weeks Cover | M3: Cost of Stock | N3: Sales | O3: Physical Qty | P3: On Order | Q3: Sell-Through | R3: Weeks Cover | S3: Cost of Stock | T3: Sales | U3: Physical Qty | V3: On Order | W3: Sell-Through | X3: Weeks Cover | Y3: Cost of Stock | Z3: Sales | AA3: Physical Qty | AB3: On Order | AC3: Sell-Through | AD3: Weeks Cover | AE3: Cost of Stock | AF3: Sales | AG3: Physical Qty | AH3: On Order | AI3: Sell-Through | AJ3: Weeks Cover | AK3: Cost of Stock | AL3: Sales | AM3: Physical Qty | AN3: On Order | AO3: Sell-Through | AP3: Weeks Cover | AQ3: Cost of Stock | AR3: Sales | AS3: Physical Qty | AT3: On Order | AU3: Sell-Through | AV3: Weeks Cover | AW3: Cost of Stock | AX3: Sales | AY3: Physical Qty | AZ3: On Order | BA3: Sell-Through | BB3: Weeks Cover | BC3: Cost of Stock | BD3: Sales | BE3: Physical Qty | BF3: On Order | BG3: Sell-Through | BH3: Weeks Cover | BI3: Cost of Stock | BJ3: Sales | BK3: Physical Qty | BL3: On Order | BM3: Sell-Through | BN3: Weeks Cover | BO3: Cost of Stock | BP3: Sales | BQ3: Physical Qty | BR3: On Order | BS3: Sell-Through | BT3: Weeks Cover | BU3: Cost of Stock | BV3: Sales | BW3: Physical Qty | BX3: On Order | BY3: Sell-Through | BZ3: Weeks Cover | CA3: Cost of Stock | CB3: Sales | CC3: Physical Qty | CD3: On Order | CE3: Sell-Through | CF3: Weeks Cover | CG3: Cost of Stock | CH3: Sales | CI3: Physical Qty | CJ3: On Order | CK3: Sell-Through | CL3: Weeks Cover | CM3: Cost of Stock | CN3: Sales | CO3: Physical Qty | CP3: On Order | CQ3: Sell-Through | CR3: Weeks Cover | CS3: Cost of Stock | DA3: 1st MD | DB3: Ratio | DC3: 2ND MD | DD3: Ratio | DE3: 3RD MD | DF3: Ratio | DG3: 4TH MD | DH3: Ratio
A4: Accessories | B4: Accessories | C4: EARTH SQUARED LTD CEN | D4: 103164 | E4: SS22 GINCAT SPRING GINGHAM CAT PURSE | F4: BLUE | G4: 9.99 | H4: 0 | I4: 2 | J4: 0 | K4: 0 | L4: 2 | M4: 8.32 | T4: 0 | U4: 2 | V4: 0 | W4: 0 | X4: 2 | Y4: 8.32 | Z4: 1 | AA4: -1 | AB4: 3 | AC4: 1 | AD4: 8 | AE4: -4.16 | AF4: 0 | AG4: 4 | AH4: 0 | AI4: 0 | AJ4: 4 | AK4: 16.64 | AR4: 0 | AS4: 1 | AT4: 0 | AU4: 0 | AV4: 1 | AW4: 4.16 | AX4: 0 | AY4: 4 | AZ4: 3 | BA4: 0 | BB4: 7 | BC4: 16.64 | BD4: 0 | BE4: 2 | BF4: 2 | BG4: 0 | BH4: 4 | BI4: 8.32 | BP4: 0 | BQ4: 3 | BR4: 0 | BS4: 0 | BT4: 3 | BU4: 12.48 | BV4: 2 | BW4: 1 | BX4: 0 | BY4: 0.66666667 | BZ4: 4 | CA4: 4.16 | CB4: 0 | CC4: 2 | CD4: 0 | CE4: 0 | CF4: 2 | CG4: 8.32 | CT4: 3 | CU4: 20 | CV4: 8 | CW4: 0.16666667 | CX4: 37 | CY4: 83.2 | DB4: =IF(DA4="","",1-(DA4/Main!$G4)) | DC4: 5 | DD4: =IF(DC4="","",1-(DC4/Main!$G4)) -> 0.4994995 | DE4: 3 | DF4: =IF(DE4="","",1-(DE4/Main!$G4)) -> 0.6996997 | DG4: =IF(DF4="","",1-(DF4/Main!$G4)) -> 0.92995999 | DH4: =IF(DG4="","",1-(DG4/Main!$G4)) -> 0.90691091
A5: Accessories | B5: Accessories | C5: EARTH SQUARED LTD CEN | D5: 103164 | E5: SS22 GINCAT SPRING GINGHAM CAT PURSE | F5: Grey | G5: 9.99 | H5: 0 | I5: 2 | J5: 0 | K5: 0 | L5: 2 | M5: 8.32 | T5: 0 | U5: 2 | V5: 0 | W5: 0 | X5: 2 | Y5: 8.32 | Z5: 0 | AA5: -2 | AB5: 3 | AC5: 0 | AD5: 1 | AE5: -8.32 | AF5: 0 | AG5: 4 | AH5: 0 | AI5: 0 | AJ5: 4 | AK5: 16.64 | AR5: 0 | AS5: 1 | AT5: 0 | AU5: 0 | AV5: 1 | AW5: 4.16 | AX5: 0 | AY5: 4 | AZ5: 3 | BA5: 0 | BB5: 7 | BC5: 16.64 | BD5: 0 | BE5: 2 | BF5: 2 | BG5: 0 | BH5: 4 | BI5: 8.32 | BP5: 0 | BQ5: 3 | BR5: 0 | BS5: 0 | BT5: 3 | BU5: 12.48 | BV5: 2 | BW5: 0 | BX5: 0 | BY5: 1 | BZ5: 0 | CA5: 0 | CB5: 1 | CC5: 1 | CD5: 0 | CE5: 0.5 | CF5: 4 | CG5: 4.16 | CT5: 3 | CU5: 17 | CV5: 8 | CW5: 0.15 | CX5: 28 | CY5: 70.72 | DB5: =IF(DA5="","",1-(DA5/Main!$G5)) | DD5: =IF(DC5="","",1-(DC5/Main!$G5)) | DF5: =IF(DE5="","",1-(DE5/Main!$G5)) | DH5: =IF(DG5="","",1-(DG5/Main!$G5))
A6: Accessories | B6: Accessories | C6: EARTH SQUARED LTD CEN | D6: 103164 | E6: SS22 GINCAT SPRING GINGHAM CAT PURSE | F6: RED | G6: 9.99 | H6: 1 | I6: 1 | J6: 0 | K6: 0.5 | L6: 4 | M6: 4.16 | T6: 0 | U6: 1 | V6: 0 | W6: 0 | X6: 1 | Y6: 4.16 | Z6: 3 | AA6: -3 | AB6: 3 | AC6: 1 | AD6: 0 | AE6: -12.48 | AF6: 0 | AG6: 4 | AH6: 0 | AI6: 0 | AJ6: 4 | AK6: 16.64 | AR6: 2 | AS6: 0 | AT6: 0 | AU6: 1 | AV6: 0 | AW6: 0 | AX6: 1 | AY6: 3 | AZ6: 3 | BA6: 0.25 | BB6: 24 | BC6: 12.48 | BD6: 0 | BE6: 2 | BF6: 2 | BG6: 0 | BH6: 4 | BI6: 8.32 | BJ6: 2 | BK6: 0 | BL6: 0 | BM6: 1 | BN6: 0 | BO6: 0 | BP6: 0 | BQ6: 3 | BR6: 0 | BS6: 0 | BT6: 3 | BU6: 12.48 | BV6: 1 | BW6: 1 | BX6: 0 | BY6: 0.5 | BZ6: 4 | CA6: 4.16 | CB6: 0 | CC6: 2 | CD6: 0 | CE6: 0 | CF6: 2 | CG6: 8.32 | CT6: 10 | CU6: 14 | CV6: 8 | CW6: 0.38636364 | CX6: 46 | CY6: 58.24 | DB6: =IF(DA6="","",1-(DA6/Main!$G6)) | DD6: =IF(DC6="","",1-(DC6/Main!$G6)) | DF6: =IF(DE6="","",1-(DE6/Main!$G6)) | DH6: =IF(DG6="","",1-(DG6/Main!$G6))
A7: Accessories | B7: Accessories | C7: EARTH SQUARED LTD CEN | D7: 103165 | E7: SS22 SOMPURBL SPRING PATCHWORK PLEAT PURSE | F7: Navy | G7: 9.99 | H7: 0 | I7: 1 | J7: 1 | K7: 0 | L7: 2 | M7: 4.16 | T7: 0 | U7: 1 | V7: 0 | W7: 0 | X7: 1 | Y7: 4.16 | Z7: 0 | AA7: 0 | AB7: 3 | AC7: 0 | AD7: 3 | AE7: 0 | AR7: 0 | AS7: 2 | AT7: 0 | AU7: 0 | AV7: 2 | AW7: 8.32 | AX7: 0 | AY7: 0 | AZ7: 4 | BA7: 0 | BB7: 4 | BC7: 0 | BD7: 0 | BE7: 2 | BF7: 2 | BG7: 0 | BH7: 4 | BI7: 8.32 | BP7: 0 | BQ7: 4 | BR7: 0 | BS7: 0 | BT7: 4 | BU7: 16.64 | CB7: 0 | CC7: 2 | CD7: 0 | CE7: 0 | CF7: 2 | CG7: 8.32 | CT7: 0 | CU7: 12 | CV7: 10 | CW7: 0 | CX7: 22 | CY7: 49.92 | DB7: =IF(DA7="","",1-(DA7/Main!$G7)) | DD7: =IF(DC7="","",1-(DC7/Main!$G7)) | DF7: =IF(DE7="","",1-(DE7/Main!$G7)) | DH7: =IF(DG7="","",1-(DG7/Main!$G7))
A8: Accessories | B8: Accessories | C8: EARTH SQUARED LTD CEN | D8: 103166 | E8: SS22 SOMPURGY BLUE SPRING BLOSSOM CANVAS JULIET PURSE | F8: Grey | G8: 9.99 | H8: 0 | I8: 1 | J8: 1 | K8: 0 | L8: 2 | M8: 4.16 | Z8: 0 | AA8: 0 | AB8: 5 | AC8: 0 | AD8: 5 | AE8: 0 | AF8: 0 | AG8: 4 | AH8: 0 | AI8: 0 | AJ8: 4 | AK8: 16.64 | AR8: 0 | AS8: 2 | AT8: 0 | AU8: 0 | AV8: 2 | AW8: 8.32 | AX8: 0 | AY8: 4 | AZ8: 3 | BA8: 0 | BB8: 7 | BC8: 16.64 | BD8: 0 | BE8: 2 | BF8: 2 | BG8: 0 | BH8: 4 | BI8: 8.32 | BJ8: 0 | BK8: 2 | BL8: 0 | BM8: 0 | BN8: 2 | BO8: 8.32 | BP8: 0 | BQ8: 4 | BR8: 0 | BS8: 0 | BT8: 4 | BU8: 16.64 | BV8: 0 | BW8: 1 | BX8: 0 | BY8: 0 | BZ8: 1 | CA8: 4.16 | CB8: 0 | CC8: 2 | CD8: 0 | CE8: 0 | CF8: 2 | CG8: 8.32 | CT8: 0 | CU8: 22 | CV8: 11 | CW8: 0 | CX8: 33 | CY8: 91.52 | DB8: =IF(DA8="","",1-(DA8/Main!$G8)) | DD8: =IF(DC8="","",1-(DC8/Main!$G8)) | DF8: =IF(DE8="","",1-(DE8/Main!$G8)) | DH8: =IF(DG8="","",1-(DG8/Main!$G8))
A9: Accessories | B9: Accessories | C9: EARTH SQUARED LTD CEN | D9: 103167 | E9: BEEJP ANIMAL APPLIQUE JULIET PURSE | F9: Multi | G9: 9.99 | H9: 3 | I9: 0 | J9: 2 | K9: 1 | L9: 4 | M9: 0 | T9: 0 | U9: 4 | V9: 1 | W9: 0 | X9: 5 | Y9: 16.64 | Z9: 0 | AA9: 3 | AB9: 5 | AC9: 0 | AD9: 8 | AE9: 12.48 | AF9: 4 | AG9: 7 | AH9: 0 | AI9: 0.36363636 | AJ9: 28 | AK9: 29.12 | AR9: 0 | AS9: 0 | AT9: 3 | AU9: 0 | AV9: 3 | AW9: 0 | AX9: 1 | AY9: 3 | AZ9: 3 | BA9: 0.25 | BB9: 24 | BC9: 12.48 | BD9: 0 | BE9: 7 | BF9: 4 | BG9: 0 | BH9: 11 | BI9: 29.12 | BJ9: 0 | BK9: 4 | BL9: 1 | BM9: 0 | BN9: 5 | BO9: 16.64 | BP9: 3 | BQ9: 5 | BR9: 1 | BS9: 0.375 | BT9: 24 | BU9: 20.8 | BV9: 0 | BW9: 0 | BX9: 3 | BY9: 0 | BZ9: 3 | CA9: 0 | CB9: 0 | CC9: 0 | CD9: 3 | CE9: 0 | CF9: 3 | CG9: 0 | CT9: 11 | CU9: 33 | CV9: 26 | CW9: 0.18078512 | CX9: 118 | CY9: 137.28 | DB9: =IF(DA9="","",1-(DA9/Main!$G9)) | DD9: =IF(DC9="","",1-(DC9/Main!$G9)) | DF9: =IF(DE9="","",1-(DE9/Main!$G9)) | DH9: =IF(DG9="","",1-(DG9/Main!$G9))
A10: Accessories | B10: Accessories | C10: EARTH SQUARED LTD CEN | D10: 103171 | E10: SS22 DOGJP DOG ANIMAL APPLIQUE JULIET PURSE | F10: Multi | G10: 9.99 | H10: 0 | I10: 0 | J10: 3 | K10: 0 | L10: 3 | M10: 0 | T10: 0 | U10: 0 | V10: 4 | W10: 0 | X10: 4 | Y10: 0 | Z10: 0 | AA10: -1 | AB10: 5 | AC10: 0 | AD10: 4 | AE10: -4.16 | AF10: 0 | AG10: 4 | AH10: 0 | AI10: 0 | AJ10: 4 | AK10: 16.64 | AR10: 0 | AS10: 0 | AT10: 4 | AU10: 0 | AV10: 4 | AW10: 0 | AX10: 1 | AY10: 3 | AZ10: 3 | BA10: 0.25 | BB10: 24 | BC10: 12.48 | BD10: 0 | BE10: 3 | BF10: 3 | BG10: 0 | BH10: 6 | BI10: 12.48 | BJ10: 0 | BK10: 1 | BL10: 4 | BM10: 0 | BN10: 5 | BO10: 4.16 | BP10: 0 | BQ10: 3 | BR10: 4 | BS10: 0 | BT10: 7 | BU10: 12.48 | CB10: 0 | CC10: 0 | CD10: 4 | CE10: 0 | CF10: 4 | CG10: 0 | CT10: 1 | CU10: 13 | CV10: 34 | CW10: 0.025 | CX10: 65 | CY10: 54.08 | DB10: =IF(DA10="","",1-(DA10/Main!$G10)) | DD10: =IF(DC10="","",1-(DC10/Main!$G10)) | DF10: =IF(DE10="","",1-(DE10/Main!$G10)) | DH10: =IF(DG10="","",1-(DG10/Main!$G10))
A11: Accessories | B11: Accessories | C11: EARTH SQUARED LTD CEN | D11: 103172 | E11: SS22 DOGEYE DOG ANIMAL APPLIQUE EYE GLASS CASE | F11: Multi | G11: 9.99 | H11: 0 | I11: 1 | J11: 2 | K11: 0 | L11: 3 | M11: 4.16 | T11: 3 | U11: 2 | V11: 2 | W11: 0.6 | X11: 16 | Y11: 8.32 | Z11: 0 | AA11: -1 | AB11: 5 | AC11: 0 | AD11: 4 | AE11: -4.16 | AF11: 0 | AG11: 4 | AH11: 0 | AI11: 0 | AJ11: 4 | AK11: 16.64 | AR11: 0 | AS11: 1 | AT11: 2 | AU11: 0 | AV11: 3 | AW11: 4.16 | AX11: 0 | AY11: 4 | AZ11: 3 | BA11: 0 | BB11: 7 | BC11: 16.64 | BD11: 0 | BE11: 3 | BF11: 3 | BG11: 0 | BH11: 6 | BI11: 12.48 | BJ11: 0 | BK11: 0 | BL11: 4 | BM11: 0 | BN11: 4 | BO11: 0 | BP11: 0 | BQ11: 4 | BR11: 2 | BS11: 0 | BT11: 6 | BU11: 16.64 | BV11: 1 | BW11: 1 | BX11: 1 | BY11: 0.5 | BZ11: 8 | CA11: 4.16 | CB11: 0 | CC11: 0 | CD11: 7 | CE11: 0 | CF11: 7 | CG11: 0 | CT11: 4 | CU11: 19 | CV11: 31 | CW11: 0.1 | CX11: 68 | CY11: 79.04 | DB11: =IF(DA11="","",1-(DA11/Main!$G11)) | DD11: =IF(DC11="","",1-(DC11/Main!$G11)) | DF11: =IF(DE11="","",1-(DE11/Main!$G11)) | DH11: =IF(DG11="","",1-(DG11/Main!$G11))
A12: Accessories | B12: Accessories | C12: EARTH SQUARED LTD CEN | D12: 103255 | E12: SS22 HCOWJP COW ANIMAL APPLIQUE JULIET PURSE | F12: Multi | G12: 9.99 | H12: 0 | I12: 0 | J12: 2 | K12: 0 | L12: 2 | M12: 0 | T12: 0 | U12: 0 | V12: 2 | W12: 0 | X12: 2 | Y12: 0 | Z12: 0 | AA12: -1 | AB12: 2 | AC12: 0 | AD12: 1 | AE12: -4.16 | AF12: 0 | AG12: 0 | AH12: 2 | AI12: 0 | AJ12: 2 | AK12: 0 | AR12: 0 | AS12: 1 | AT12: 2 | AU12: 0 | AV12: 3 | AW12: 4.16 | BD12: 0 | BE12: 0 | BF12: 2 | BG12: 0 | BH12: 2 | BI12: 0 | BJ12: 0 | BK12: 0 | BL12: 2 | BM12: 0 | BN12: 2 | BO12: 0 | BP12: 0 | BQ12: 1 | BR12: 2 | BS12: 0 | BT12: 3 | BU12: 4.16 | BV12: 0 | BW12: 0 | BX12: 2 | BY12: 0 | BZ12: 2 | CA12: 0 | CB12: 0 | CC12: 0 | CD12: 2 | CE12: 0 | CF12: 2 | CG12: 0 | CT12: 0 | CU12: 1 | CV12: 20 | CW12: 0 | CX12: 21 | CY12: 4.16 | DB12: =IF(DA12="","",1-(DA12/Main!$G12)) | DD12: =IF(DC12="","",1-(DC12/Main!$G12)) | DF12: =IF(DE12="","",1-(DE12/Main!$G12)) | DH12: =IF(DG12="","",1-(DG12/Main!$G12))
A13: Accessories | B13: Accessories | C13: EARTH SQUARED LTD CEN | D13: 103256 | E13: SS22 BEEEYE BEE ANIMAL APPLIQUE EYE GLASS CASE | F13: Multi | G13: 9.99 | H13: 0 | I13: 1 | J13: 3 | K13: 0 | L13: 4 | M13: 4.16 | T13: 0 | U13: 5 | V13: 0 | W13: 0 | X13: 5 | Y13: 20.8 | Z13: 0 | AA13: 8 | AB13: 4 | AC13: 0 | AD13: 12 | AE13: 33.28 | AF13: 4 | AG13: 3 | AH13: 0 | AI13: 0.57142857 | AJ13: 12 | AK13: 12.48 | AR13: 0 | AS13: 1 | AT13: 2 | AU13: 0 | AV13: 3 | AW13: 4.16 | AX13: 0 | AY13: 0 | AZ13: 3 | BA13: 0 | BB13: 3 | BC13: 0 | BD13: 0 | BE13: 5 | BF13: 3 | BG13: 0 | BH13: 8 | BI13: 20.8 | BJ13: 0 | BK13: 4 | BL13: 2 | BM13: 0 | BN13: 6 | BO13: 16.64 | BP13: 0 | BQ13: 2 | BR13: 4 | BS13: 0 | BT13: 6 | BU13: 8.32 | BV13: 0 | BW13: 1 | BX13: 2 | BY13: 0 | BZ13: 3 | CA13: 4.16 | CT13: 4 | CU13: 30 | CV13: 23 | CW13: 0.057142857 | CX13: 62 | CY13: 124.8 | DB13: =IF(DA13="","",1-(DA13/Main!$G13)) | DD13: =IF(DC13="","",1-(DC13/Main!$G13)) | DF13: =IF(DE13="","",1-(DE13/Main!$G13)) | DH13: =IF(DG13="","",1-(DG13/Main!$G13))
A14: Accessories | B14: Accessories | C14: EARTH SQUARED LTD CEN | D14: 103257 | E14: SS22 HCOWEYE | F14: Multi | G14: 9.99 | H14: 0 | I14: 0 | J14: 2 | K14: 0 | L14: 2 | M14: 0 | T14: 0 | U14: 0 | V14: 2 | W14: 0 | X14: 2 | Y14: 0 | Z14: 0 | AA14: 0 | AB14: 2 | AC14: 0 | AD14: 2 | AE14: 0 | AF14: 0 | AG14: 0 | AH14: 2 | AI14: 0 | AJ14: 2 | AK14: 0 | AR14: 0 | AS14: 0 | AT14: 2 | AU14: 0 | AV14: 2 | AW14: 0 | BD14: 0 | BE14: 0 | BF14: 2 | BG14: 0 | BH14: 2 | BI14: 0 | BP14: 4 | BQ14: 0 | BR14: 2 | BS14: 1 | BT14: 3 | BU14: 0 | BV14: 0 | BW14: 0 | BX14: 2 | BY14: 0 | BZ14: 2 | CA14: 0 | CT14: 4 | CU14: 0 | CV14: 16 | CW14: 0.125 | CX14: 17 | CY14: 0 | DB14: =IF(DA14="","",1-(DA14/Main!$G14)) | DD14: =IF(DC14="","",1-(DC14/Main!$G14)) | DF14: =IF(DE14="","",1-(DE14/Main!$G14)) | DH14: =IF(DG14="","",1-(DG14/Main!$G14))
A15: Accessories | B15: Accessories | C15: (blank) | D15: 103158 | E15: SS22 ASSTD FNJ | F15: Asstd | G15: 9.99 | H15: 94 | I15: 31 | J15: 82 | K15: 0.752 | L15: 22 | M15: 80.6 | N15: 31 | O15: 53 | P15: 0 | Q15: 0.36904762 | R15: 24 | S15: 137.8 | T15: 46 | U15: 83 | V15: 0 | W15: 0.35658915 | X15: 24 | Y15: 215.8 | Z15: 85 | AA15: 36 | AB15: 83 | AC15: 0.70247934 | AD15: 26 | AE15: 93.6 | AF15: 53 | AG15: -70 | AH15: 0 | AI15: 1 | AJ15: 0 | AK15: -182 | AL15: 52 | AM15: 33 | AN15: 0 | AO15: 0.61176471 | AP15: 11 | AQ15: 85.8 | AR15: 72 | AS15: 10 | AT15: 80 | AU15: 0.87804878 | AV15: 72 | AW15: 26 | AX15: 76 | AY15: 43 | AZ15: 80 | BA15: 0.63865546 | BB15: 38 | BC15: 111.8 | BD15: 80 | BE15: 44 | BF15: 80 | BG15: 0.64516129 | BH15: 33 | BI15: 114.4 | BJ15: 32 | BK15: 91 | BL15: 0 | BM15: 0.2601626 | BN15: 73 | BO15: 236.6 | BP15: 75 | BQ15: 49 | BR15: 0 | BS15: 0.60483871 | BT15: 10 | BU15: 127.4 | BV15: 33 | BW15: 47 | BX15: 80 | BY15: 0.4125 | BZ15: 127 | CA15: 122.2 | CB15: 65 | CC15: 22 | CD15: 0 | CE15: 0.74712644 | CF15: 15 | CG15: 57.2 | CT15: 794 | CU15: 472 | CV15: 485 | CW15: 0.61372108 | CX15: 475 | CY15: 1227.2 | DB15: =IF(DA15="","",1-(DA15/Main!$G15)) | DD15: =IF(DC15="","",1-(DC15/Main!$G15)) | DF15: =IF(DE15="","",1-(DE15/Main!$G15)) | DH15: =IF(DG15="","",1-(DG15/Main!$G15))
A16: Accessories | B16: Gifts | C16: FAYE UK LTD CENPAC | D16: 102603 | E16: SS22 THERMAL COFFEE MUG | F16: Asstd | G16: 19.99 | H16: 0 | I16: 5 | J16: 0 | K16: 0 | L16: 5 | M16: 41.65 | N16: 0 | O16: 6 | P16: 0 | Q16: 0 | R16: 6 | S16: 49.98 | T16: 0 | U16: 6 | V16: 0 | W16: 0 | X16: 6 | Y16: 49.98 | Z16: 0 | AA16: 4 | AB16: 0 | AC16: 0 | AD16: 4 | AE16: 33.32 | AF16: 0 | AG16: 5 | AH16: 0 | AI16: 0 | AJ16: 5 | AK16: 41.65 | AL16: 0 | AM16: 6 | AN16: 0 | AO16: 0 | AP16: 6 | AQ16: 49.98 | AR16: 0 | AS16: 0 | AT16: 6 | AU16: 0 | AV16: 6 | AW16: 0 | AX16: 0 | AY16: 5 | AZ16: 0 | BA16: 0 | BB16: 5 | BC16: 41.65 | BD16: 0 | BE16: 5 | BF16: 0 | BG16: 0 | BH16: 5 | BI16: 41.65 | BJ16: 1 | BK16: 5 | BL16: 0 | BM16: 0.16666667 | BN16: 20 | BO16: 41.65 | BP16: 0 | BQ16: 3 | BR16: 0 | BS16: 0 | BT16: 3 | BU16: 24.99 | CT16: 1 | CU16: 50 | CV16: 6 | CW16: 0.015151515 | CX16: 71 | CY16: 416.5 | DB16: =IF(DA16="","",1-(DA16/Main!$G16)) | DD16: =IF(DC16="","",1-(DC16/Main!$G16)) | DF16: =IF(DE16="","",1-(DE16/Main!$G16)) | DH16: =IF(DG16="","",1-(DG16/Main!$G16))
A17: Accessories | B17: Gifts | C17: FAYE UK LTD CENPAC | D17: 102830 | E17: SS22 ASSORTED CROSSBODY 4BAG | F17: Asstd | G17: 17.99 | H17: 0 | I17: 6 | J17: 0 | K17: 0 | L17: 6 | M17: 45 | N17: 1 | O17: 7 | P17: 0 | Q17: 0.125 | R17: 28 | S17: 52.5 | T17: 0 | U17: 7 | V17: 0 | W17: 0 | X17: 7 | Y17: 52.5 | Z17: 0 | AA17: 3 | AB17: 0 | AC17: 0 | AD17: 3 | AE17: 22.5 | AL17: 0 | AM17: 8 | AN17: 0 | AO17: 0 | AP17: 8 | AQ17: 60 | BD17: 0 | BE17: 6 | BF17: 0 | BG17: 0 | BH17: 6 | BI17: 45 | BJ17: 2 | BK17: 6 | BL17: 0 | BM17: 0.25 | BN17: 24 | BO17: 45 | BP17: 0 | BQ17: 7 | BR17: 0 | BS17: 0 | BT17: 7 | BU17: 52.5 | CT17: 3 | CU17: 50 | CV17: 0 | CW17: 0.046875 | CX17: 89 | CY17: 375 | DB17: =IF(DA17="","",1-(DA17/Main!$G17)) | DD17: =IF(DC17="","",1-(DC17/Main!$G17)) | DF17: =IF(DE17="","",1-(DE17/Main!$G17)) | DH17: =IF(DG17="","",1-(DG17/Main!$G17))
A18: Accessories | B18: Gifts | C18: FAYE UK LTD CENPAC | D18: 102831 | E18: SS22 B43PK FOLD BACKPACK | F18: Asstd | G18: 19.99 | H18: 0 | I18: 13 | J18: 0 | K18: 0 | L18: 52 | M18: 108.29 | N18: 0 | O18: 15 | P18: 0 | Q18: 0 | R18: 15 | S18: 124.95 | T18: 0 | U18: 13 | V18: 0 | W18: 0 | X18: 13 | Y18: 108.29 | Z18: 8 | AA18: 8 | AB18: 0 | AC18: 0.5 | AD18: 8 | AE18: 66.64 | AF18: 4 | AG18: 11 | AH18: 0 | AI18: 0.26666667 | AJ18: 22 | AK18: 91.63 | AL18: 2 | AM18: 14 | AN18: 0 | AO18: 0.125 | AP18: 28 | AQ18: 116.62 | AR18: 0 | AS18: -2 | AT18: 20 | AU18: 0 | AV18: 18 | AW18: -16.66 | AX18: 7 | AY18: 9 | AZ18: 0 | BA18: 0.4375 | BB18: 9 | BC18: 74.97 | BD18: 8 | BE18: 8 | BF18: 0 | BG18: 0.5 | BH18: 8 | BI18: 66.64 | BJ18: 0 | BK18: 16 | BL18: 0 | BM18: 0 | BN18: 16 | BO18: 133.28 | BP18: 4 | BQ18: 11 | BR18: 0 | BS18: 0.26666667 | BT18: 22 | BU18: 91.63 | BV18: 0 | BW18: -1 | BX18: 0 | BY18: 0 | BZ18: 0 | CA18: -8.33 | CT18: 33 | CU18: 115 | CV18: 20 | CW18: 0.17465278 | CX18: 211 | CY18: 957.95 | DB18: =IF(DA18="","",1-(DA18/Main!$G18)) | DD18: =IF(DC18="","",1-(DC18/Main!$G18)) | DF18: =IF(DE18="","",1-(DE18/Main!$G18)) | DH18: =IF(DG18="","",1-(DG18/Main!$G18))
A19: Accessories | B19: Gifts | C19: FAYE UK LTD CENPAC | D19: 102832 | E19: SS22 B50MB FOLDAWAY BACKPACK PLAIN | F19: Asstd | G19: 19.99 | H19: 1 | I19: 3 | J19: 0 | K19: 0.25 | L19: 12 | M19: 24.99 | N19: 0 | O19: 3 | P19: 0 | Q19: 0 | R19: 3 | S19: 24.99 | T19: 1 | U19: 2 | V19: 0 | W19: 0.33333333 | X19: 8 | Y19: 16.66 | Z19: 3 | AA19: 1 | AB19: 0 | AC19: 0.75 | AD19: 4 | AE19: 8.33 | AF19: 0 | AG19: 3 | AH19: 0 | AI19: 0 | AJ19: 3 | AK19: 24.99 | AL19: 2 | AM19: 2 | AN19: 0 | AO19: 0.5 | AP19: 8 | AQ19: 16.66 | AX19: 0 | AY19: 3 | AZ19: 0 | BA19: 0 | BB19: 3 | BC19: 24.99 | BD19: 1 | BE19: 3 | BF19: 0 | BG19: 0.25 | BH19: 12 | BI19: 24.99 | BJ19: 0 | BK19: 3 | BL19: 0 | BM19: 0 | BN19: 3 | BO19: 24.99 | BP19: 4 | BQ19: 0 | BR19: 0 | BS19: 1 | BT19: 0 | BU19: 0 | BV19: 0 | BW19: 4 | BX19: 0 | BY19: 0 | BZ19: 4 | CA19: 33.32 | CB19: 4 | CC19: 2 | CD19: 0 | CE19: 0.66666667 | CF19: 8 | CG19: 16.66 | CT19: 16 | CU19: 29 | CV19: 0 | CW19: 0.3125 | CX19: 68 | CY19: 241.57 | DB19: =IF(DA19="","",1-(DA19/Main!$G19)) | DD19: =IF(DC19="","",1-(DC19/Main!$G19)) | DF19: =IF(DE19="","",1-(DE19/Main!$G19)) | DH19: =IF(DG19="","",1-(DG19/Main!$G19))
A20: Accessories | B20: Gifts | C20: FAYE UK LTD CENPAC | D20: 102833 | E20: SS22 ECO SHOPPER | F20: Asstd | G20: 5.99 | H20: 5 | I20: 41 | J20: 0 | K20: 0.10869565 | L20: 23 | M20: 102.5 | N20: 3 | O20: 45 | P20: 0 | Q20: 0.0625 | R20: 60 | S20: 112.5 | T20: 1 | U20: 47 | V20: 0 | W20: 0.020833333 | X20: 188 | Y20: 117.5 | Z20: 2 | AA20: 44 | AB20: 0 | AC20: 0.043478261 | AD20: 44 | AE20: 110 | AF20: 0 | AG20: 48 | AH20: 0 | AI20: 0 | AJ20: 48 | AK20: 120 | AL20: 6 | AM20: 42 | AN20: 0 | AO20: 0.125 | AP20: 28 | AQ20: 105 | AR20: 5 | AS20: -5 | AT20: 48 | AU20: 1 | AV20: 34 | AW20: -12.5 | AX20: 5 | AY20: 43 | AZ20: 0 | BA20: 0.10416667 | BB20: 34 | BC20: 107.5 | BD20: 4 | BE20: 44 | BF20: 0 | BG20: 0.083333333 | BH20: 44 | BI20: 110 | BJ20: 4 | BK20: 44 | BL20: 0 | BM20: 0.083333333 | BN20: 44 | BO20: 110 | BP20: 4 | BQ20: 43 | BR20: 0 | BS20: 0.085106383 | BT20: 34 | BU20: 107.5 | BV20: 1 | BW20: 46 | BX20: 0 | BY20: 0.021276596 | BZ20: 92 | CA20: 115 | CB20: 0 | CC20: 25 | CD20: 0 | CE20: 0 | CF20: 25 | CG20: 62.5 | CT20: 40 | CU20: 507 | CV20: 48 | CW20: 0.13367104 | CX20: 698 | CY20: 1267.5 | DB20: =IF(DA20="","",1-(DA20/Main!$G20)) | DD20: =IF(DC20="","",1-(DC20/Main!$G20)) | DF20: =IF(DE20="","",1-(DE20/Main!$G20)) | DH20: =IF(DG20="","",1-(DG20/Main!$G20))
A21: Accessories | B21: Gifts | C21: FAYE UK LTD CENPAC | D21: 102835 | E21: SS22 FOLDABLE HOLDALL | F21: Asstd | G21: 19.99 | Z21: 0 | AA21: 13 | AB21: 0 | AC21: 0 | AD21: 13 | AE21: 108.29 | AF21: 0 | AG21: 12 | AH21: 0 | AI21: 0 | AJ21: 12 | AK21: 99.96 | AL21: 0 | AM21: 11 | AN21: 0 | AO21: 0 | AP21: 11 | AQ21: 91.63 | AR21: 0 | AS21: 0 | AT21: 14 | AU21: 0 | AV21: 14 | AW21: 0 | AX21: 0 | AY21: 12 | AZ21: 0 | BA21: 0 | BB21: 12 | BC21: 99.96 | BJ21: 0 | BK21: 14 | BL21: 0 | BM21: 0 | BN21: 14 | BO21: 116.62 | BP21: 0 | BQ21: 0 | BR21: 14 | BS21: 0 | BT21: 14 | BU21: 0 | CT21: 0 | CU21: 62 | CV21: 28 | CW21: 0 | CX21: 90 | CY21: 516.46 | DB21: =IF(DA21="","",1-(DA21/Main!$G21)) | DD21: =IF(DC21="","",1-(DC21/Main!$G21)) | DF21: =IF(DE21="","",1-(DE21/Main!$G21)) | DH21: =IF(DG21="","",1-(DG21/Main!$G21))
A22: Accessories | B22: Gifts | C22: FAYE UK LTD CENPAC | D22: 103777 | E22: SS22 LARGE COOL BAG E17TL | F22: Asstd | G22: 13.99 | T22: 0 | U22: 12 | V22: 0 | W22: 0 | X22: 12 | Y22: 69.96 | AR22: 1 | AS22: -1 | AT22: 12 | AU22: 1 | AV22: 44 | AW22: -5.83 | BP22: 1 | BQ22: 11 | BR22: 0 | BS22: 0.083333333 | BT22: 44 | BU22: 64.13 | CT22: 2 | CU22: 22 | CV22: 12 | CW22: 0.36111111 | CX22: 100 | CY22: 128.26 | DB22: =IF(DA22="","",1-(DA22/Main!$G22)) | DD22: =IF(DC22="","",1-(DC22/Main!$G22)) | DF22: =IF(DE22="","",1-(DE22/Main!$G22)) | DH22: =IF(DG22="","",1-(DG22/Main!$G22))
A23: Accessories | B23: Gifts | C23: FAYE UK LTD CENPAC | D23: 105660 | E23: SS22 BACK PACK COOLER | F23: Asstd | G23: 26.99 | BP23: 0 | BQ23: 0 | BR23: 9 | BS23: 0 | BT23: 9 | BU23: 0 | CT23: 0 | CU23: 0 | CV23: 9 | CW23: 0 | CX23: 9 | CY23: 0 | DB23: =IF(DA23="","",1-(DA23/Main!$G23)) | DD23: =IF(DC23="","",1-(DC23/Main!$G23)) | DF23: =IF(DE23="","",1-(DE23/Main!$G23)) | DH23: =IF(DG23="","",1-(DG23/Main!$G23))
A24: Accessories | B24: Gifts | C24: FAYE UK LTD CENPAC | D24: 105661 | E24: SS22 LRG ADULT PONCHO | F24: Asstd | G24: 17.99 | AL24: 0 | AM24: 0 | AN24: 8 | AO24: 0 | AP24: 8 | AQ24: 0 | AX24: 0 | AY24: 0 | AZ24: 8 | BA24: 0 | BB24: 8 | BC24: 0 | BP24: 0 | BQ24: 0 | BR24: 8 | BS24: 0 | BT24: 8 | BU24: 0 | CT24: 0 | CU24: 0 | CV24: 24 | CW24: 0 | CX24: 24 | CY24: 0 | DB24: =IF(DA24="","",1-(DA24/Main!$G24)) | DD24: =IF(DC24="","",1-(DC24/Main!$G24)) | DF24: =IF(DE24="","",1-(DE24/Main!$G24)) | DH24: =IF(DG24="","",1-(DG24/Main!$G24))
A25: Accessories | B25: Gifts | C25: MAD BEAUTY LTD | D25: 103133 | E25: SS22 FB-FG5563 IN FULL BLOOM WATERING CAN GIFT SET | F25: Multi | G25: 13.99 | H25: 0 | I25: 3 | J25: 0 | K25: 0 | L25: 3 | M25: 17.49 | T25: 0 | U25: 4 | V25: 0 | W25: 0 | X25: 4 | Y25: 23.32 | Z25: 4 | AA25: 3 | AB25: 0 | AC25: 0.57142857 | AD25: 12 | AE25: 17.49 | AF25: 1 | AG25: 0 | AH25: 0 | AI25: 1 | AJ25: 0 | AK25: 0 | AL25: 0 | AM25: 4 | AN25: 0 | AO25: 0 | AP25: 4 | AQ25: 23.32 | AR25: 0 | AS25: 4 | AT25: 0 | AU25: 0 | AV25: 4 | AW25: 23.32 | AX25: 8 | AY25: 1 | AZ25: 0 | BA25: 0.88888889 | BB25: 1 | BC25: 5.83 | BD25: 0 | BE25: 5 | BF25: 0 | BG25: 0 | BH25: 5 | BI25: 29.15 | BJ25: 3 | BK25: 0 | BL25: 3 | BM25: 1 | BN25: 12 | BO25: 0 | BP25: 0 | BQ25: 4 | BR25: 0 | BS25: 0 | BT25: 4 | BU25: 23.32 | BV25: 2 | BW25: 0 | BX25: 0 | BY25: 1 | BZ25: 0 | CA25: 0 | CB25: 0 | CC25: 2 | CD25: 0 | CE25: 0 | CF25: 2 | CG25: 11.66 | CT25: 18 | CU25: 30 | CV25: 3 | CW25: 0.37169312 | CX25: 51 | CY25: 174.9 | DB25: =IF(DA25="","",1-(DA25/Main!$G25)) | DD25: =IF(DC25="","",1-(DC25/Main!$G25)) | DF25: =IF(DE25="","",1-(DE25/Main!$G25)) | DH25: =IF(DG25="","",1-(DG25/Main!$G25))
A26: Accessories | B26: Gifts | C26: MAD BEAUTY LTD | D26: 103134 | E26: SS22 FB-FG5560 IN FULL BLOOM BATH SALT S | F26: Multi | G26: 3.5 | H26: 0 | I26: 6 | J26: 0 | K26: 0 | L26: 6 | M26: 8.76 | T26: 0 | U26: 5 | V26: 0 | W26: 0 | X26: 5 | Y26: 7.3 | Z26: 0 | AA26: 6 | AB26: 0 | AC26: 0 | AD26: 6 | AE26: 8.76 | AF26: 2 | AG26: 4 | AH26: 0 | AI26: 0.33333333 | AJ26: 16 | AK26: 5.84 | AL26: 0 | AM26: 10 | AN26: 0 | AO26: 0 | AP26: 10 | AQ26: 14.6 | AR26: 0 | AS26: 5 | AT26: 0 | AU26: 0 | AV26: 5 | AW26: 7.3 | AX26: 0 | AY26: 5 | AZ26: 0 | BA26: 0 | BB26: 5 | BC26: 7.3 | BD26: 0 | BE26: 5 | BF26: 0 | BG26: 0 | BH26: 5 | BI26: 7.3 | BJ26: 0 | BK26: 3 | BL26: 6 | BM26: 0 | BN26: 9 | BO26: 4.38 | BP26: 0 | BQ26: 5 | BR26: 0 | BS26: 0 | BT26: 5 | BU26: 7.3 | BV26: 0 | BW26: 6 | BX26: 0 | BY26: 0 | BZ26: 6 | CA26: 8.76 | CB26: 2 | CC26: 4 | CD26: 0 | CE26: 0.33333333 | CF26: 16 | CG26: 5.84 | CN26: 0 | CO26: 6 | CP26: 0 | CQ26: 0 | CR26: 6 | CS26: 8.76 | CT26: 4 | CU26: 70 | CV26: 6 | CW26: 0.051282051 | CX26: 100 | CY26: 102.2 | DB26: =IF(DA26="","",1-(DA26/Main!$G26)) | DD26: =IF(DC26="","",1-(DC26/Main!$G26)) | DF26: =IF(DE26="","",1-(DE26/Main!$G26)) | DH26: =IF(DG26="","",1-(DG26/Main!$G26))
A27: Accessories | B27: Gifts | C27: MAD BEAUTY LTD | D27: 103135 | E27: SS22 FB-FG5544-6 IN FULL BLOOM HAND CARE SET | F27: Multi | G27: 4.99 | H27: 0 | I27: 4 | J27: 0 | K27: 0 | L27: 4 | M27: 8.32 | T27: 0 | U27: 5 | V27: 0 | W27: 0 | X27: 5 | Y27: 10.4 | Z27: 0 | AA27: 5 | AB27: 0 | AC27: 0 | AD27: 5 | AE27: 10.4 | AF27: 0 | AG27: 5 | AH27: 0 | AI27: 0 | AJ27: 5 | AK27: 10.4 | AL27: 5 | AM27: 4 | AN27: 0 | AO27: 0.55555556 | AP27: 16 | AQ27: 8.32 | AR27: 0 | AS27: 5 | AT27: 0 | AU27: 0 | AV27: 5 | AW27: 10.4 | AX27: 2 | AY27: 4 | AZ27: 0 | BA27: 0.33333333 | BB27: 16 | BC27: 8.32 | BD27: 0 | BE27: 2 | BF27: 0 | BG27: 0 | BH27: 2 | BI27: 4.16 | BJ27: 3 | BK27: 0 | BL27: 3 | BM27: 1 | BN27: 6 | BO27: 0 | BP27: 0 | BQ27: 3 | BR27: 0 | BS27: 0 | BT27: 3 | BU27: 6.24 | BV27: 0 | BW27: 3 | BX27: 0 | BY27: 0 | BZ27: 3 | CA27: 6.24 | CB27: 0 | CC27: 1 | CD27: 0 | CE27: 0 | CF27: 1 | CG27: 2.08 | CN27: 0 | CO27: 3 | CP27: 0 | CQ27: 0 | CR27: 3 | CS27: 6.24 | CT27: 10 | CU27: 44 | CV27: 3 | CW27: 0.14529915 | CX27: 74 | CY27: 91.52 | DB27: =IF(DA27="","",1-(DA27/Main!$G27)) | DD27: =IF(DC27="","",1-(DC27/Main!$G27)) | DF27: =IF(DE27="","",1-(DE27/Main!$G27)) | DH27: =IF(DG27="","",1-(DG27/Main!$G27))
A28: Accessories | B28: Gifts | C28: MAD BEAUTY LTD | D28: 103136 | E28: SS22 FB-FG5557-6 IN FULL BLOOM MELTING BATH PETALS | F28: Multi | G28: 10.99 | H28: 0 | I28: 1 | J28: 0 | K28: 0 | L28: 1 | M28: 4.58 | N28: 0 | O28: 3 | P28: 0 | Q28: 0 | R28: 3 | S28: 13.74 | T28: 0 | U28: 3 | V28: 0 | W28: 0 | X28: 3 | Y28: 13.74 | Z28: 0 | AA28: 3 | AB28: 0 | AC28: 0 | AD28: 3 | AE28: 13.74 | AF28: 0 | AG28: 1 | AH28: 0 | AI28: 0 | AJ28: 1 | AK28: 4.58 | AL28: 1 | AM28: 2 | AN28: 0 | AO28: 0.33333333 | AP28: 8 | AQ28: 9.16 | AR28: 0 | AS28: 1 | AT28: 0 | AU28: 0 | AV28: 1 | AW28: 4.58 | AX28: 0 | AY28: 4 | AZ28: 0 | BA28: 0 | BB28: 4 | BC28: 18.32 | BD28: 0 | BE28: 3 | BF28: 0 | BG28: 0 | BH28: 3 | BI28: 13.74 | BJ28: 0 | BK28: 1 | BL28: 3 | BM28: 0 | BN28: 4 | BO28: 4.58 | BP28: 3 | BQ28: 0 | BR28: 0 | BS28: 1 | BT28: 0 | BU28: 0 | CB28: 1 | CC28: 2 | CD28: 0 | CE28: 0.33333333 | CF28: 8 | CG28: 9.16 | CT28: 5 | CU28: 24 | CV28: 3 | CW28: 0.13888889 | CX28: 39 | CY28: 109.92 | DB28: =IF(DA28="","",1-(DA28/Main!$G28)) | DD28: =IF(DC28="","",1-(DC28/Main!$G28)) | DF28: =IF(DE28="","",1-(DE28/Main!$G28)) | DH28: =IF(DG28="","",1-(DG28/Main!$G28))
A29: Accessories | B29: Gifts | C29: MAD BEAUTY LTD | D29: 103137 | E29: SS22 MBHSG-24 | F29: Multi | G29: 2.99 | H29: 0 | I29: 47 | J29: 0 | K29: 0 | L29: 188 | M29: 58.75 | N29: 3 | O29: 45 | P29: 0 | Q29: 0.0625 | R29: 60 | S29: 56.25 | Z29: 2 | AA29: 46 | AB29: 0 | AC29: 0.041666667 | AD29: 92 | AE29: 57.5 | AL29: 0 | AM29: 48 | AN29: 0 | AO29: 0 | AP29: 48 | AQ29: 60 | AX29: 0 | AY29: -4 | AZ29: 0 | BA29: 0 | BB29: 0 | BC29: -5 | BD29: 0 | BE29: 48 | BF29: 0 | BG29: 0 | BH29: 48 | BI29: 60 | BJ29: 0 | BK29: 24 | BL29: 12 | BM29: 0 | BN29: 36 | BO29: 30 | BP29: 0 | BQ29: -1 | BR29: 0 | BS29: 0 | BT29: 0 | BU29: -1.25 | CB29: 0 | CC29: -2 | CD29: 0 | CE29: 0 | CF29: 0 | CG29: -2.5 | CT29: 5 | CU29: 251 | CV29: 12 | CW29: 0.011574074 | CX29: 472 | CY29: 313.75 | DB29: =IF(DA29="","",1-(DA29/Main!$G29)) | DD29: =IF(DC29="","",1-(DC29/Main!$G29)) | DF29: =IF(DE29="","",1-(DE29/Main!$G29)) | DH29: =IF(DG29="","",1-(DG29/Main!$G29))
A30: Accessories | B30: Gifts | C30: MAD BEAUTY LTD | D30: 103138 | E30: SS22 MBD-FG2559-EU24 DOGS HAND CLEANSING GEL | F30: Multi | G30: 2.5 | H30: 0 | I30: 48 | J30: 0 | K30: 0 | L30: 48 | M30: 50.4 | N30: 0 | O30: 24 | P30: 0 | Q30: 0 | R30: 24 | S30: 25.2 | Z30: 0 | AA30: 48 | AB30: 0 | AC30: 0 | AD30: 48 | AE30: 50.4 | AL30: 0 | AM30: 48 | AN30: 0 | AO30: 0 | AP30: 48 | AQ30: 50.4 | BD30: 0 | BE30: 48 | BF30: 0 | BG30: 0 | BH30: 48 | BI30: 50.4 | BJ30: 0 | BK30: 24 | BL30: 12 | BM30: 0 | BN30: 36 | BO30: 25.2 | CT30: 0 | CU30: 240 | CV30: 12 | CW30: 0 | CX30: 252 | CY30: 252 | DB30: =IF(DA30="","",1-(DA30/Main!$G30)) | DD30: =IF(DC30="","",1-(DC30/Main!$G30)) | DF30: =IF(DE30="","",1-(DE30/Main!$G30)) | DH30: =IF(DG30="","",1-(DG30/Main!$G30))
A31: Accessories | B31: Gifts | C31: MAD BEAUTY LTD | D31: 103139 | E31: SS22 MBHSS-24 | F31: Multi | G31: 2.99 | H31: 0 | I31: 24 | J31: 0 | K31: 0 | L31: 24 | M31: 30 | Z31: 0 | AA31: 36 | AB31: 12 | AC31: 0 | AD31: 48 | AE31: 45 | AL31: 0 | AM31: 36 | AN31: 12 | AO31: 0 | AP31: 48 | AQ31: 45 | BD31: 0 | BE31: 48 | BF31: 0 | BG31: 0 | BH31: 48 | BI31: 60 | BJ31: 0 | BK31: 24 | BL31: 12 | BM31: 0 | BN31: 36 | BO31: 30 | CT31: 0 | CU31: 168 | CV31: 36 | CW31: 0 | CX31: 204 | CY31: 210 | DB31: =IF(DA31="","",1-(DA31/Main!$G31)) | DD31: =IF(DC31="","",1-(DC31/Main!$G31)) | DF31: =IF(DE31="","",1-(DE31/Main!$G31)) | DH31: =IF(DG31="","",1-(DG31/Main!$G31))
A32: Accessories | B32: Gifts | C32: MAD BEAUTY LTD | D32: 103140 | E32: SS22 MBHSM1-24 | F32: Multi | G32: 2.99 | H32: 0 | I32: 24 | J32: 0 | K32: 0 | L32: 24 | M32: 30 | Z32: 0 | AA32: 48 | AB32: 0 | AC32: 0 | AD32: 48 | AE32: 60 | AL32: 0 | AM32: 48 | AN32: 0 | AO32: 0 | AP32: 48 | AQ32: 60 | BJ32: 0 | BK32: 24 | BL32: 12 | BM32: 0 | BN32: 36 | BO32: 30 | CT32: 0 | CU32: 144 | CV32: 12 | CW32: 0 | CX32: 156 | CY32: 180 | DB32: =IF(DA32="","",1-(DA32/Main!$G32)) | DD32: =IF(DC32="","",1-(DC32/Main!$G32)) | DF32: =IF(DE32="","",1-(DE32/Main!$G32)) | DH32: =IF(DG32="","",1-(DG32/Main!$G32))
A33: Accessories | B33: Gifts | C33: REX INTERNATIONAL | D33: 103141 | E33: SS22 28656 LOVE BIRDS LUNCH BAG | F33: Multi | G33: 4.95 | H33: 0 | I33: 8 | J33: 0 | K33: 0 | L33: 8 | M33: 13.2 | N33: 2 | O33: 5 | P33: 0 | Q33: 0.28571429 | R33: 20 | S33: 8.25 | T33: 0 | U33: 9 | V33: 0 | W33: 0 | X33: 9 | Y33: 14.85 | Z33: 0 | AA33: 6 | AB33: 0 | AC33: 0 | AD33: 6 | AE33: 9.9 | AF33: 2 | AG33: 8 | AH33: 0 | AI33: 0.2 | AJ33: 32 | AK33: 13.2 | AL33: 3 | AM33: 4 | AN33: 0 | AO33: 0.42857143 | AP33: 16 | AQ33: 6.6 | AR33: 0 | AS33: 7 | AT33: 0 | AU33: 0 | AV33: 7 | AW33: 11.55 | AX33: 0 | AY33: 9 | AZ33: 0 | BA33: 0 | BB33: 9 | BC33: 14.85 | BD33: 0 | BE33: 5 | BF33: 0 | BG33: 0 | BH33: 5 | BI33: 8.25 | BJ33: 0 | BK33: 6 | BL33: 0 | BM33: 0 | BN33: 6 | BO33: 9.9 | BP33: 0 | BQ33: 5 | BR33: 0 | BS33: 0 | BT33: 5 | BU33: 8.25 | BV33: 0 | BW33: 5 | BX33: 0 | BY33: 0 | BZ33: 5 | CA33: 8.25 | CB33: 0 | CC33: 2 | CD33: 0 | CE33: 0 | CF33: 2 | CG33: 3.3 | CN33: 0 | CO33: 3 | CP33: 0 | CQ33: 0 | CR33: 3 | CS33: 4.95 | CT33: 7 | CU33: 82 | CV33: 0 | CW33: 0.065306122 | CX33: 133 | CY33: 135.3 | DB33: =IF(DA33="","",1-(DA33/Main!$G33)) | DD33: =IF(DC33="","",1-(DC33/Main!$G33)) | DF33: =IF(DE33="","",1-(DE33/Main!$G33)) | DH33: =IF(DG33="","",1-(DG33/Main!$G33))
A34: Accessories | B34: Gifts | C34: REX INTERNATIONAL | D34: 103142 | E34: SS22 28659 LOVE BIRDS SHOPPING BAG | F34: Multi | G34: 3.95 | H34: 3 | I34: 4 | J34: 0 | K34: 0.42857143 | L34: 16 | M34: 5.8 | N34: 0 | O34: 7 | P34: 0 | Q34: 0 | R34: 7 | S34: 10.15 | T34: 2 | U34: 9 | V34: 0 | W34: 0.18181818 | X34: 36 | Y34: 13.05 | Z34: 0 | AA34: 7 | AB34: 0 | AC34: 0 | AD34: 7 | AE34: 10.15 | AF34: 0 | AG34: 10 | AH34: 0 | AI34: 0 | AJ34: 10 | AK34: 14.5 | AL34: 1 | AM34: 3 | AN34: 0 | AO34: 0.25 | AP34: 12 | AQ34: 4.35 | AR34: 0 | AS34: 7 | AT34: 0 | AU34: 0 | AV34: 7 | AW34: 10.15 | AX34: 0 | AY34: 10 | AZ34: 0 | BA34: 0 | BB34: 10 | BC34: 14.5 | BD34: 5 | BE34: 3 | BF34: 0 | BG34: 0.625 | BH34: 12 | BI34: 4.35 | BJ34: 0 | BK34: 6 | BL34: 0 | BM34: 0 | BN34: 6 | BO34: 8.7 | BP34: 4 | BQ34: 7 | BR34: 0 | BS34: 0.36363636 | BT34: 28 | BU34: 10.15 | BV34: 0 | BW34: 7 | BX34: 0 | BY34: 0 | BZ34: 7 | CA34: 10.15 | CB34: 0 | CC34: 3 | CD34: 0 | CE34: 0 | CF34: 3 | CG34: 4.35 | CN34: 0 | CO34: 4 | CP34: 0 | CQ34: 0 | CR34: 4 | CS34: 5.8 | CT34: 15 | CU34: 87 | CV34: 0 | CW34: 0.13207328 | CX34: 165 | CY34: 126.15 | DB34: =IF(DA34="","",1-(DA34/Main!$G34)) | DD34: =IF(DC34="","",1-(DC34/Main!$G34)) | DF34: =IF(DE34="","",1-(DE34/Main!$G34)) | DH34: =IF(DG34="","",1-(DG34/Main!$G34))
A35: Accessories | B35: Gifts | C35: REX INTERNATIONAL | D35: 103143 | E35: SS22 28801 LOVE BIRDS CARD HOLDER PURSE | F35: Multi | G35: 6.95 | H35: 1 | I35: 5 | J35: 0 | K35: 0.16666667 | L35: 20 | M35: 12.45 | N35: 1 | O35: 2 | P35: 0 | Q35: 0.33333333 | R35: 8 | S35: 4.98 | T35: 0 | U35: 6 | V35: 0 | W35: 0 | X35: 6 | Y35: 14.94 | Z35: 0 | AA35: 3 | AB35: 0 | AC35: 0 | AD35: 3 | AE35: 7.47 | AF35: 1 | AG35: 2 | AH35: 0 | AI35: 0.33333333 | AJ35: 8 | AK35: 4.98 | AL35: 0 | AM35: 3 | AN35: 0 | AO35: 0 | AP35: 3 | AQ35: 7.47 | AR35: 0 | AS35: 3 | AT35: 0 | AU35: 0 | AV35: 3 | AW35: 7.47 | AX35: 0 | AY35: 3 | AZ35: 0 | BA35: 0 | BB35: 3 | BC35: 7.47 | BD35: 0 | BE35: 2 | BF35: 0 | BG35: 0 | BH35: 2 | BI35: 4.98 | BJ35: 0 | BK35: 2 | BL35: 0 | BM35: 0 | BN35: 2 | BO35: 4.98 | BP35: 2 | BQ35: 2 | BR35: 0 | BS35: 0.5 | BT35: 4 | BU35: 4.98 | BV35: 0 | BW35: 3 | BX35: 0 | BY35: 0 | BZ35: 3 | CA35: 7.47 | CB35: 0 | CC35: 3 | CD35: 0 | CE35: 0 | CF35: 3 | CG35: 7.47 | CT35: 5 | CU35: 39 | CV35: 0 | CW35: 0.1025641 | CX35: 68 | CY35: 97.11 | DB35: =IF(DA35="","",1-(DA35/Main!$G35)) | DD35: =IF(DC35="","",1-(DC35/Main!$G35)) | DF35: =IF(DE35="","",1-(DE35/Main!$G35)) | DH35: =IF(DG35="","",1-(DG35/Main!$G35))
A36: Accessories | B36: Gifts | C36: REX INTERNATIONAL | D36: 103144 | E36: SS22 28805 LOVE BIRDS PURSE | F36: Multi | G36: 5.95 | H36: 0 | I36: 6 | J36: 0 | K36: 0 | L36: 6 | M36: 12.48 | T36: 3 | U36: 1 | V36: 0 | W36: 0.75 | X36: 4 | Y36: 2.08 | Z36: 0 | AA36: 1 | AB36: 0 | AC36: 0 | AD36: 1 | AE36: 2.08 | AF36: 0 | AG36: 5 | AH36: 0 | AI36: 0 | AJ36: 5 | AK36: 10.4 | AL36: 0 | AM36: 3 | AN36: 0 | AO36: 0 | AP36: 3 | AQ36: 6.24 | AR36: 0 | AS36: 2 | AT36: 0 | AU36: 0 | AV36: 2 | AW36: 4.16 | AX36: 0 | AY36: 5 | AZ36: 0 | BA36: 0 | BB36: 5 | BC36: 10.4 | BD36: 0 | BE36: 1 | BF36: 0 | BG36: 0 | BH36: 1 | BI36: 2.08 | BJ36: 0 | BK36: 2 | BL36: 0 | BM36: 0 | BN36: 2 | BO36: 4.16 | BP36: 0 | BQ36: 3 | BR36: 0 | BS36: 0 | BT36: 3 | BU36: 6.24 | BV36: 0 | BW36: 3 | BX36: 0 | BY36: 0 | BZ36: 3 | CA36: 6.24 | CB36: 3 | CC36: 0 | CD36: 0 | CE36: 1 | CF36: 0 | CG36: 0 | CT36: 6 | CU36: 32 | CV36: 0 | CW36: 0.14583333 | CX36: 35 | CY36: 66.56 | DB36: =IF(DA36="","",1-(DA36/Main!$G36)) | DD36: =IF(DC36="","",1-(DC36/Main!$G36)) | DF36: =IF(DE36="","",1-(DE36/Main!$G36)) | DH36: =IF(DG36="","",1-(DG36/Main!$G36))
A37: Accessories | B37: Gifts | C37: REX INTERNATIONAL | D37: 103145 | E37: SS22 28841 LOVE BIRDS MAGNETIC SHOPPING LIST | F37: Multi | G37: 3.95 | H37: 6 | I37: 0 | J37: 0 | K37: 1 | L37: 0 | M37: 0 | T37: 3 | U37: 4 | V37: 0 | W37: 0.42857143 | X37: 16 | Y37: 5.8 | Z37: 3 | AA37: 0 | AB37: 0 | AC37: 1 | AD37: 0 | AE37: 0 | AL37: 0 | AM37: 2 | AN37: 0 | AO37: 0 | AP37: 2 | AQ37: 2.9 | AR37: 0 | AS37: 2 | AT37: 0 | AU37: 0 | AV37: 2 | AW37: 2.9 | BJ37: 0 | BK37: 1 | BL37: 0 | BM37: 0 | BN37: 1 | BO37: 1.45 | BP37: 0 | BQ37: 3 | BR37: 0 | BS37: 0 | BT37: 3 | BU37: 4.35 | BV37: 2 | BW37: 1 | BX37: 0 | BY37: 0.66666667 | BZ37: 4 | CA37: 1.45 | CB37: 2 | CC37: 1 | CD37: 0 | CE37: 0.66666667 | CF37: 4 | CG37: 1.45 | CT37: 16 | CU37: 14 | CV37: 0 | CW37: 0.41798942 | CX37: 32 | CY37: 20.3 | DB37: =IF(DA37="","",1-(DA37/Main!$G37)) | DD37: =IF(DC37="","",1-(DC37/Main!$G37)) | DF37: =IF(DE37="","",1-(DE37/Main!$G37)) | DH37: =IF(DG37="","",1-(DG37/Main!$G37))
A38: Accessories | B38: Gifts | C38: REX INTERNATIONAL | D38: 103146 | E38: SS22 28972 LOVE BIRDS GLASSES CASE & CLEANING CLOTH | F38: Multi | G38: 4.95 | N38: 3 | O38: 1 | P38: 0 | Q38: 0.75 | R38: 4 | S38: 1.79 | T38: 0 | U38: 4 | V38: 0 | W38: 0 | X38: 4 | Y38: 7.16 | Z38: 0 | AA38: 2 | AB38: 0 | AC38: 0 | AD38: 2 | AE38: 3.58 | AF38: 0 | AG38: 2 | AH38: 0 | AI38: 0 | AJ38: 2 | AK38: 3.58 | AX38: 0 | AY38: 2 | AZ38: 0 | BA38: 0 | BB38: 2 | BC38: 3.58 | BD38: 0 | BE38: 1 | BF38: 0 | BG38: 0 | BH38: 1 | BI38: 1.79 | BJ38: 0 | BK38: 1 | BL38: 0 | BM38: 0 | BN38: 1 | BO38: 1.79 | BP38: 0 | BQ38: 3 | BR38: 0 | BS38: 0 | BT38: 3 | BU38: 5.37 | CB38: 3 | CC38: 0 | CD38: 0 | CE38: 1 | CF38: 0 | CG38: 0 | CT38: 6 | CU38: 16 | CV38: 0 | CW38: 0.19444444 | CX38: 19 | CY38: 28.64 | DB38: =IF(DA38="","",1-(DA38/Main!$G38)) | DD38: =IF(DC38="","",1-(DC38/Main!$G38)) | DF38: =IF(DE38="","",1-(DE38/Main!$G38)) | DH38: =IF(DG38="","",1-(DG38/Main!$G38))
A39: Accessories | B39: Gifts | C39: REX INTERNATIONAL | D39: 103147 | E39: SS22 29130 LOVE BIRDS 420ML GLASS DRINKING BOTTLE | F39: Multi | G39: 9.95 | H39: 0 | I39: 4 | J39: 0 | K39: 0 | L39: 4 | M39: 15 | T39: 0 | U39: 2 | V39: 0 | W39: 0 | X39: 2 | Y39: 7.5 | Z39: 2 | AA39: 1 | AB39: 0 | AC39: 0.66666667 | AD39: 4 | AE39: 3.75 | AF39: 0 | AG39: 3 | AH39: 0 | AI39: 0 | AJ39: 3 | AK39: 11.25 | AL39: 0 | AM39: 1 | AN39: 0 | AO39: 0 | AP39: 1 | AQ39: 3.75 | AR39: 0 | AS39: 3 | AT39: 0 | AU39: 0 | AV39: 3 | AW39: 11.25 | AX39: 0 | AY39: 3 | AZ39: 0 | BA39: 0 | BB39: 3 | BC39: 11.25 | BD39: 4 | BE39: 2 | BF39: 0 | BG39: 0.66666667 | BH39: 8 | BI39: 7.5 | BJ39: 0 | BK39: 3 | BL39: 0 | BM39: 0 | BN39: 3 | BO39: 11.25 | BP39: 0 | BQ39: 3 | BR39: 0 | BS39: 0 | BT39: 3 | BU39: 11.25 | CB39: 0 | CC39: 3 | CD39: 0 | CE39: 0 | CF39: 3 | CG39: 11.25 | CT39: 6 | CU39: 28 | CV39: 0 | CW39: 0.12121212 | CX39: 37 | CY39: 105 | DB39: =IF(DA39="","",1-(DA39/Main!$G39)) | DD39: =IF(DC39="","",1-(DC39/Main!$G39)) | DF39: =IF(DE39="","",1-(DE39/Main!$G39)) | DH39: =IF(DG39="","",1-(DG39/Main!$G39))
A40: Accessories | B40: Gifts | C40: REX INTERNATIONAL | D40: 103148 | E40: SS22 29148 ASSORTED RECYCLED SHOPPER BAGS | F40: Multi | G40: 5.95 | H40: 24 | I40: 39 | J40: 0 | K40: 0.38095238 | L40: 31 | M40: 81.12 | N40: 6 | O40: 10 | P40: 0 | Q40: 0.375 | R40: 10 | S40: 20.8 | T40: 12 | U40: 22 | V40: 0 | W40: 0.35294118 | X40: 22 | Y40: 45.76 | Z40: 15 | AA40: 12 | AB40: 0 | AC40: 0.55555556 | AD40: 6 | AE40: 24.96 | AF40: 4 | AG40: -2 | AH40: 0 | AI40: 2 | AJ40: 0 | AK40: -4.16 | AL40: 9 | AM40: 18 | AN40: 0 | AO40: 0.33333333 | AP40: 12 | AQ40: 37.44 | AR40: 6 | AS40: 21 | AT40: 0 | AU40: 0.22222222 | AV40: 42 | AW40: 43.68 | AX40: 13 | AY40: 43 | AZ40: 0 | BA40: 0.23214286 | BB40: 86 | BC40: 89.44 | BD40: 4 | BE40: 10 | BF40: 0 | BG40: 0.28571429 | BH40: 40 | BI40: 20.8 | BJ40: 17 | BK40: 7 | BL40: 0 | BM40: 0.70833333 | BN40: 5 | BO40: 14.56 | BP40: 7 | BQ40: 23 | BR40: 0 | BS40: 0.23333333 | BT40: 31 | BU40: 47.84 | BV40: 0 | BW40: 17 | BX40: 0 | BY40: 0 | BZ40: 17 | CA40: 35.36 | CB40: 6 | CC40: 21 | CD40: 0 | CE40: 0.22222222 | CF40: 42 | CG40: 43.68 | CN40: 0 | CO40: 4 | CP40: 0 | CQ40: 0 | CR40: 4 | CS40: 8.32 | CT40: 123 | CU40: 245 | CV40: 0 | CW40: 0.42155362 | CX40: 348 | CY40: 509.6 | DB40: =IF(DA40="","",1-(DA40/Main!$G40)) | DD40: =IF(DC40="","",1-(DC40/Main!$G40)) | DF40: =IF(DE40="","",1-(DE40/Main!$G40)) | DH40: =IF(DG40="","",1-(DG40/Main!$G40))
...

Sheet Summary
C1: Branch Code | D1: Values
C2: 1 | G2: 2 | K2: 3 | O2: 4 | S2: 5 | W2: 6 | AA2: 8 | AE2: 9 | AI2: 11 | AM2: 12 | AQ2: 13 | AU2: 15 | AY2: 16 | BC2: 90 | BG2: 990 | BK2: Total Sales | BL2: Total Stock | BM2: Total Sell-Through | BN2: Total Weekly Cover
A3: SectionCode | B3: SectionName | C3: Sales | D3: Stock | E3: Sell-Through | F3: Weekly Cover | G3: Sales | H3: Stock | I3: Sell-Through | J3: Weekly Cover | K3: Sales | L3: Stock | M3: Sell-Through | N3: Weekly Cover | O3: Sales | P3: Stock | Q3: Sell-Through | R3: Weekly Cover | S3: Sales | T3: Stock | U3: Sell-Through | V3: Weekly Cover | W3: Sales | X3: Stock | Y3: Sell-Through | Z3: Weekly Cover | AA3: Sales | AB3: Stock | AC3: Sell-Through | AD3: Weekly Cover | AE3: Sales | AF3: Stock | AG3: Sell-Through | AH3: Weekly Cover | AI3: Sales | AJ3: Stock | AK3: Sell-Through | AL3: Weekly Cover | AM3: Sales | AN3: Stock | AO3: Sell-Through | AP3: Weekly Cover | AQ3: Sales | AR3: Stock | AS3: Sell-Through | AT3: Weekly Cover | AU3: Sales | AV3: Stock | AW3: Sell-Through | AX3: Weekly Cover | AY3: Sales | AZ3: Stock | BA3: Sell-Through | BB3: Weekly Cover | BC3: Sales | BD3: Stock | BE3: Sell-Through | BF3: Weekly Cover | BG3: Sales | BH3: Stock | BI3: Sell-Through | BJ3: Weekly Cover
A4: 2 | B4: Handbags | C4: 49 | D4: 217 | E4: 0.18421053 | F4: 55 | G4: 11 | H4: 226 | I4: 0.046413502 | J4: 76 | K4: 49 | L4: 249 | M4: 0.16442953 | N4: 54 | O4: 60 | P4: 177 | Q4: 0.25316456 | R4: 35 | S4: 47 | T4: 294 | U4: 0.13782991 | V4: 43 | W4: 45 | X4: 252 | Y4: 0.15151515 | Z4: 27 | AA4: 34 | AB4: 94 | AC4: 0.265625 | AD4: 29 | AE4: 58 | AF4: 301 | AG4: 0.16155989 | AH4: 25 | AI4: 57 | AJ4: 297 | AK4: 0.16101695 | AL4: 43 | AM4: 32 | AN4: 344 | AO4: 0.085106383 | AP4: 43 | AQ4: 53 | AR4: 252 | AS4: 0.17377049 | AT4: 29 | AU4: 43 | AV4: 262 | AW4: 0.14098361 | AX4: 31 | AY4: 36 | AZ4: 231 | BA4: 0.13483146 | BB4: 28 | BC4: 0 | BD4: -28 | BE4: 0 | BF4: -28 | BK4: 574 | BL4: 3168 | BM4: 0.1471755 | BN4: 490
A5: 5 | B5: Gifts | C5: 77 | D5: 380 | E5: 0.16849015 | F5: 56 | G5: 29 | H5: 219 | I5: 0.11693548 | J5: 41 | K5: 42 | L5: 245 | M5: 0.14634146 | N5: 75 | O5: 46 | P5: 329 | Q5: 0.12266667 | R5: 52 | S5: 31 | T5: 171 | U5: 0.15346535 | V5: 45 | W5: 58 | X5: 370 | Y5: 0.13551402 | Z5: 60 | AA5: 32 | AB5: 94 | AC5: 0.25396825 | AD5: 45 | AE5: 71 | AF5: 209 | AG5: 0.25357143 | AH5: 29 | AI5: 31 | AJ5: 312 | AK5: 0.090379009 | AL5: 83 | AM5: 32 | AN5: 250 | AO5: 0.11347518 | AP5: 73 | AQ5: 49 | AR5: 214 | AS5: 0.18631179 | AT5: 37 | AU5: 6 | AV5: 147 | AW5: 0.039215686 | AX5: 84 | AY5: 54 | AZ5: 80 | BA5: 0.40298507 | BB5: 13 | BG5: 0 | BH5: 43 | BI5: 0 | BJ5: 43 | BK5: 558 | BL5: 3063 | BM5: 0.1559514 | BN5: 736
A6: 9 | B6: Accessories | C6: 98 | D6: 40 | E6: 0.71014493 | F6: 23 | G6: 31 | H6: 53 | I6: 0.36904762 | J6: 23 | K6: 49 | L6: 100 | M6: 0.32885906 | N6: 29 | O6: 89 | P6: 38 | Q6: 0.7007874 | R6: 29 | S6: 61 | T6: -36 | U6: 2.44 | V6: -12 | W6: 52 | X6: 33 | Y6: 0.61176471 | Z6: 11 | AA6: 74 | AB6: 19 | AC6: 0.79569892 | AD6: 76 | AE6: 79 | AF6: 68 | AG6: 0.53741497 | AH6: 44 | AI6: 80 | AJ6: 72 | AK6: 0.52631579 | AL6: 47 | AM6: 34 | AN6: 102 | AO6: 0.25 | AP6: 76 | AQ6: 82 | AR6: 81 | AS6: 0.50306748 | AT6: 16 | AU6: 39 | AV6: 52 | AW6: 0.42857143 | AX6: 71 | AY6: 66 | AZ6: 31 | BA6: 0.68041237 | BB6: 26 | BK6: 834 | BL6: 653 | BM6: 0.68323728 | BN6: 459
A7: 24 | B7: Bras | S7: 0 | T7: 1 | U7: 0 | V7: 1 | BK7: 0 | BL7: 1 | BM7: 0 | BN7: 1
A8: 41 | B8: Rainwear | C8: 41 | D8: 229 | E8: 0.15185185 | F8: 33 | G8: 30 | H8: 137 | I8: 0.17964072 | J8: 23 | K8: 28 | L8: 156 | M8: 0.15217391 | N8: 38 | O8: 46 | P8: 180 | Q8: 0.20353982 | R8: 20 | S8: 49 | T8: 224 | U8: 0.17948718 | V8: 31 | W8: 47 | X8: 155 | Y8: 0.23267327 | Z8: 21 | AA8: 33 | AB8: 123 | AC8: 0.21153846 | AD8: 23 | AE8: 54 | AF8: 172 | AG8: 0.23893805 | AH8: 17 | AI8: 60 | AJ8: 174 | AK8: 0.25641026 | AL8: 21 | AM8: 54 | AN8: 142 | AO8: 0.2755102 | AP8: 30 | AQ8: 35 | AR8: 119 | AS8: 0.22727273 | AT8: 21 | AU8: 17 | AV8: 145 | AW8: 0.10493827 | AX8: 42 | AY8: 54 | AZ8: 96 | BA8: 0.36 | BB8: 18 | BG8: 0 | BH8: 22 | BI8: 0 | BJ8: 22 | BK8: 548 | BL8: 2074 | BM8: 0.19814105 | BN8: 360
A9: 80 | B9: Co-Ordinates | C9: 0 | D9: 0 | E9: 0 | F9: 4 | G9: 0 | H9: 0 | I9: 0 | J9: 12 | K9: 0 | L9: -1 | M9: 0 | N9: 11 | O9: 0 | P9: 0 | Q9: 0 | R9: 14 | S9: 0 | T9: 5 | U9: 0 | V9: 56 | W9: 0 | X9: 5 | Y9: 0 | Z9: 2 | AA9: 0 | AB9: 4 | AC9: 0 | AD9: 10 | AE9: 0 | AF9: 1 | AG9: 0 | AH9: 5 | AI9: 0 | AJ9: 0 | AK9: 0 | AL9: 4 | AM9: 0 | AN9: 4 | AO9: 0 | AP9: 20 | AQ9: 0 | AR9: 2 | AS9: 0 | AT9: 8 | AU9: 0 | AV9: 0 | AW9: 0 | AX9: 12 | AY9: 0 | AZ9: 4 | BA9: 0 | BB9: 20 | BG9: 0 | BH9: 0 | BI9: 0 | BJ9: 6 | BK9: 0 | BL9: 24 | BM9: 0 | BN9: 184
A10: 81 | B10: Blouses | C10: 0 | D10: 18 | E10: 0 | F10: 18 | G10: 0 | H10: 0 | I10: 0 | J10: 48 | K10: 0 | L10: -3 | M10: 0 | N10: 60 | O10: 0 | P10: 9 | Q10: 0 | R10: 21 | S10: 0 | T10: 24 | U10: 0 | V10: 51 | W10: 0 | X10: 42 | Y10: 0 | Z10: 16 | AA10: 0 | AB10: 20 | AC10: 0 | AD10: 73 | AE10: 0 | AF10: 19 | AG10: 0 | AH10: 36 | AI10: 0 | AJ10: 22 | AK10: 0 | AL10: 98 | AM10: 0 | AN10: 18 | AO10: 0 | AP10: 30 | AQ10: 0 | AR10: 13 | AS10: 0 | AT10: 20 | AU10: 0 | AV10: 0 | AW10: 0 | AX10: 48 | AY10: 0 | AZ10: 19 | BA10: 0 | BB10: 92 | BG10: 0 | BH10: 0 | BI10: 0 | BJ10: 24 | BK10: 0 | BL10: 201 | BM10: 0 | BN10: 635
A11: 83 | B11: Knitwear | C11: 46 | D11: 187 | E11: 0.19742489 | F11: 24 | G11: 47 | H11: 144 | I11: 0.2460733 | J11: 20 | K11: 66 | L11: 104 | M11: 0.38823529 | N11: 13 | O11: 38 | P11: 138 | Q11: 0.21590909 | R11: 30 | S11: 45 | T11: 174 | U11: 0.20547945 | V11: 27 | W11: 82 | X11: 124 | Y11: 0.39805825 | Z11: 10 | AA11: 53 | AB11: 85 | AC11: 0.38405797 | AD11: 19 | AE11: 80 | AF11: 149 | AG11: 0.34934498 | AH11: 16 | AI11: 75 | AJ11: 55 | AK11: 0.57692308 | AL11: 12 | AM11: 61 | AN11: 103 | AO11: 0.37195122 | AP11: 13 | AQ11: 47 | AR11: 158 | AS11: 0.22926829 | AT11: 21 | AU11: 35 | AV11: 98 | AW11: 0.26315789 | AX11: 33 | AY11: 53 | AZ11: 113 | BA11: 0.31927711 | BB11: 19 | BK11: 728 | BL11: 1632 | BM11: 0.31885852 | BN11: 257
A12: 84 | B12: Trousers | C12: 3 | D12: 26 | E12: 0.10344828 | F12: 74 | G12: 2 | H12: 17 | I12: 0.10526316 | J12: 258 | K12: 16 | L12: 54 | M12: 0.22857143 | N12: 40 | O12: 14 | P12: 29 | Q12: 0.3255814 | R12: 38 | S12: 1 | T12: 37 | U12: 0.026315789 | V12: 107 | W12: 5 | X12: 62 | Y12: 0.074626866 | Z12: 41 | AA12: 7 | AB12: 21 | AC12: 0.25 | AD12: 21 | AE12: 7 | AF12: 57 | AG12: 0.109375 | AH12: 176 | AI12: 3 | AJ12: 29 | AK12: 0.09375 | AL12: 58 | AM12: 7 | AN12: 69 | AO12: 0.092105263 | AP12: 64 | AQ12: 10 | AR12: 63 | AS12: 0.1369863 | AT12: 31 | AU12: 1 | AV12: 10 | AW12: 0.090909091 | AX12: 80 | AY12: 12 | AZ12: 75 | BA12: 0.13793103 | BB12: 43 | BG12: 0 | BH12: 0 | BI12: 0 | BJ12: 12 | BK12: 88 | BL12: 549 | BM12: 0.12677597 | BN12: 1043
A13: 85 | B13: Leisurewear | C13: 121 | D13: 404 | E13: 0.23047619 | F13: 21 | G13: 91 | H13: 229 | I13: 0.284375 | J13: 17 | K13: 168 | L13: 348 | M13: 0.3255814 | N13: 13 | O13: 180 | P13: 151 | Q13: 0.54380665 | R13: 9 | S13: 108 | T13: 372 | U13: 0.225 | V13: 19 | W13: 203 | X13: 354 | Y13: 0.36445242 | Z13: 10 | AA13: 125 | AB13: 205 | AC13: 0.37878788 | AD13: 14 | AE13: 155 | AF13: 353 | AG13: 0.30511811 | AH13: 15 | AI13: 94 | AJ13: 101 | AK13: 0.48205128 | AL13: 20 | AM13: 131 | AN13: 334 | AO13: 0.28172043 | AP13: 20 | AQ13: 105 | AR13: 376 | AS13: 0.21829522 | AT13: 22 | AU13: 78 | AV13: 127 | AW13: 0.3804878 | AX13: 18 | AY13: 119 | AZ13: 455 | BA13: 0.20731707 | BB13: 21 | BC13: 0 | BD13: 0 | BE13: 0 | BF13: 768 | BG13: 0 | BH13: 0 | BI13: 0 | BJ13: 3 | BK13: 1678 | BL13: 3809 | BM13: 0.2818313 | BN13: 990
A14: 103 | B14: Olsen | C14: 9 | D14: 65 | E14: 0.12162162 | F14: 36 | G14: 27 | H14: 119 | I14: 0.18493151 | J14: 30 | S14: 0 | T14: 119 | U14: 0 | V14: 119 | AE14: 5 | AF14: 120 | AG14: 0.04 | AH14: 121 | BK14: 41 | BL14: 423 | BM14: 0.086638282 | BN14: 306
A15: 123 | B15: Barbour Ladies | O15: 11 | P15: 73 | Q15: 0.13095238 | R15: 32 | AA15: 14 | AB15: 75 | AC15: 0.15730337 | AD15: 32 | AM15: 10 | AN15: 5 | AO15: 0.66666667 | AP15: 2 | AQ15: 31 | AR15: 95 | AS15: 0.24603175 | AT15: 14 | BG15: 4 | BH15: 78 | BI15: 0.048780488 | BJ15: 114 | BK15: 70 | BL15: 326 | BM15: 0.24994693 | BN15: 194
A16: 125 | B16: Joules | C16: 21 | D16: 86 | E16: 0.19626168 | F16: 45 | G16: 20 | H16: 78 | I16: 0.20408163 | J16: 22 | K16: 5 | L16: 54 | M16: 0.084745763 | N16: 61 | O16: 42 | P16: 95 | Q16: 0.30656934 | R16: 14 | S16: 12 | T16: 108 | U16: 0.1 | V16: 42 | AE16: 19 | AF16: 101 | AG16: 0.15833333 | AH16: 35 | AM16: 43 | AN16: 123 | AO16: 0.25903614 | AP16: 45 | AQ16: 27 | AR16: 114 | AS16: 0.19148936 | AT16: 27 | AU16: 11 | AV16: 52 | AW16: 0.17460317 | AX16: 82 | BG16: 4 | BH16: 106 | BI16: 0.036363636 | BJ16: 185 | BK16: 204 | BL16: 917 | BM16: 0.17114841 | BN16: 558
A17: 126 | B17: Masai | O17: 1 | P17: 3 | Q17: 0.25 | R17: 12 | AA17: 1 | AB17: 3 | AC17: 0.25 | AD17: 12 | AQ17: 0 | AR17: 5 | AS17: 0 | AT17: 5 | BK17: 2 | BL17: 11 | BM17: 0.16666667 | BN17: 29
A18: 128 | B18: Weird Fish Women | C18: 48 | D18: 78 | E18: 0.38095238 | F18: 26 | G18: 27 | H18: 27 | I18: 0.5 | J18: 20 | K18: 28 | L18: 44 | M18: 0.38888889 | N18: 19 | O18: 29 | P18: 116 | Q18: 0.2 | R18: 37 | S18: 13 | T18: 120 | U18: 0.097744361 | V18: 80 | W18: 21 | X18: 55 | Y18: 0.27631579 | Z18: 47 | AA18: 38 | AB18: 95 | AC18: 0.28571429 | AD18: 32 | AE18: 22 | AF18: 130 | AG18: 0.14473684 | AH18: 46 | AI18: 11 | AJ18: 28 | AK18: 0.28205128 | AL18: 161 | AM18: 62 | AN18: -5 | AO18: 1.0877193 | AP18: 6 | AQ18: 36 | AR18: 117 | AS18: 0.23529412 | AT18: 25 | AU18: 8 | AV18: 9 | AW18: 0.47058824 | AX18: 46 | AY18: 27 | AZ18: 129 | BA18: 0.17307692 | BB18: 36 | BG18: 5 | BH18: 144 | BI18: 0.033557047 | BJ18: 166 | BK18: 375 | BL18: 1087 | BM18: 0.32547425 | BN18: 747
A19: 130 | B19: Seasalt | C19: 96 | D19: 407 | E19: 0.19085487 | F19: 58 | K19: 29 | L19: 175 | M19: 0.14215686 | N19: 41 | O19: 61 | P19: 236 | Q19: 0.20538721 | R19: 59 | S19: 30 | T19: 223 | U19: 0.11857708 | V19: 75 | W19: 0 | X19: 1 | Y19: 0 | Z19: 1 | AA19: 41 | AB19: 170 | AC19: 0.1943128 | AD19: 63 | AE19: 63 | AF19: 193 | AG19: 0.24609375 | AH19: 37 | AM19: 78 | AN19: 92 | AO19: 0.45882353 | AP19: 35 | AQ19: 28 | AR19: 137 | AS19: 0.16969697 | AT19: 46 | AU19: 3 | AV19: 131 | AW19: 0.02238806 | AX19: 474 | BC19: 0 | BD19: -1 | BE19: 0 | BF19: -1 | BG19: 1 | BH19: 275 | BI19: 0.0036231884 | BJ19: 1792 | BK19: 430 | BL19: 2039 | BM19: 0.14599286 | BN19: 2680
A20: 131 | B20: Betty Barclay | C20: 8 | D20: 113 | E20: 0.066115702 | F20: 64 | G20: 21 | H20: 195 | I20: 0.097222222 | J20: 39 | O20: 8 | P20: 144 | Q20: 0.052631579 | R20: 64 | S20: 3 | T20: 213 | U20: 0.013888889 | V20: 284 | AA20: 19 | AB20: 110 | AC20: 0.14728682 | AD20: 24 | AE20: 23 | AF20: 199 | AG20: 0.1036036 | AH20: 49 | AM20: 5 | AN20: 27 | AO20: 0.15625 | AP20: 27 | AQ20: 14 | AR20: 101 | AS20: 0.12173913 | AT20: 29 | BG20: 0 | BH20: 208 | BI20: 0 | BJ20: 208 | BK20: 101 | BL20: 1310 | BM20: 0.084304216 | BN20: 788
A21: 132 | B21: White Stuff | C21: 51 | D21: 214 | E21: 0.19245283 | F21: 31 | K21: 9 | L21: 55 | M21: 0.140625 | N21: 59 | O21: 34 | P21: 101 | Q21: 0.25185185 | R21: 34 | S21: 0 | T21: 160 | U21: 0 | V21: 160 | AE21: 35 | AF21: 153 | AG21: 0.18617021 | AH21: 28 | AM21: 30 | AN21: 28 | AO21: 0.51724138 | AP21: 24 | AQ21: 21 | AR21: 70 | AS21: 0.23076923 | AT21: 44 | BC21: 0 | BD21: -1 | BE21: 0 | BF21: -1 | BG21: 7 | BH21: 112 | BI21: 0.058823529 | BJ21: 112 | BK21: 187 | BL21: 892 | BM21: 0.175326 | BN21: 491
A22: 136 | B22: Soya Concept | C22: 0 | D22: 6 | E22: 0 | F22: 6 | O22: 0 | P22: 2 | Q22: 0 | R22: 2 | S22: 0 | T22: 6 | U22: 0 | V22: 6 | W22: 0 | X22: 6 | Y22: 0 | Z22: 6 | AE22: 0 | AF22: 5 | AG22: 0 | AH22: 5 | AM22: 0 | AN22: 3 | AO22: 0 | AP22: 3 | BK22: 0 | BL22: 28 | BM22: 0 | BN22: 28
A23: 137 | B23: Joe Browns | G23: 8 | H23: 35 | I23: 0.18604651 | J23: 29 | O23: 18 | P23: 35 | Q23: 0.33962264 | R23: 13 | S23: 0 | T23: 36 | U23: 0 | V23: 36 | W23: 3 | X23: 20 | Y23: 0.13043478 | Z23: 57 | AE23: 4 | AF23: 32 | AG23: 0.11111111 | AH23: 49 | AM23: 0 | AN23: -10 | AO23: 0 | AP23: -10 | AY23: 7 | AZ23: 31 | BA23: 0.18421053 | BB23: 50 | BC23: 0 | BD23: -1 | BE23: 0 | BF23: -1 | BG23: 3 | BH23: 44 | BI23: 0.063829787 | BJ23: 122 | BK23: 43 | BL23: 222 | BM23: 0.11280615 | BN23: 345
A24: 139 | B24: Vero Moda | C24: 42 | D24: 79 | E24: 0.34710744 | F24: 18 | O24: 21 | P24: 94 | Q24: 0.1826087 | R24: 50 | S24: 13 | T24: 88 | U24: 0.12871287 | V24: 123 | W24: 18 | X24: 40 | Y24: 0.31034483 | Z24: 26 | AA24: 0 | AB24: 0 | AC24: 0 | AD24: 39 | AE24: 42 | AF24: 101 | AG24: 0.29370629 | AH24: 40 | AM24: 25 | AN24: 150 | AO24: 0.14285714 | AP24: 109 | AQ24: 9 | AR24: 20 | AS24: 0.31034483 | AT24: 30 | BG24: 0 | BH24: 69 | BI24: 0 | BJ24: 69 | BK24: 170 | BL24: 641 | BM24: 0.19063134 | BN24: 504
A25: 141 | B25: Superdry Ladies | C25: 0 | D25: 57 | E25: 0 | F25: 57 | G25: 10 | H25: 198 | I25: 0.048076923 | J25: 81 | K25: 8 | L25: 151 | M25: 0.050314465 | N25: 85 | O25: 11 | P25: 185 | Q25: 0.056122449 | R25: 61 | S25: 0 | T25: 119 | U25: 0 | V25: 119 | AE25: 13 | AF25: 121 | AG25: 0.097014925 | AH25: 23 | AM25: 31 | AN25: 159 | AO25: 0.16315789 | AP25: 68 | BG25: 0 | BH25: 223 | BI25: 0 | BJ25: 223 | BK25: 73 | BL25: 1213 | BM25: 0.051835832 | BN25: 717
A26: 143 | B26: Mistral | AA26: 5 | AB26: 64 | AC26: 0.072463768 | AD26: 128 | BK26: 5 | BL26: 64 | BM26: 0.072463768 | BN26: 128
A27: 158 | B27: Skechers | C27: 6 | D27: 35 | E27: 0.14634146 | F27: 29 | G27: 10 | H27: 42 | I27: 0.19230769 | J27: 21 | K27: 7 | L27: 34 | M27: 0.17073171 | N27: 21 | O27: 6 | P27: 45 | Q27: 0.11764706 | R27: 25 | S27: 1 | T27: 44 | U27: 0.022222222 | V27: 380 | W27: 11 | X27: 55 | Y27: 0.16666667 | Z27: 20 | AA27: 9 | AB27: 63 | AC27: 0.125 | AD27: 37 | AE27: 21 | AF27: 45 | AG27: 0.31818182 | AH27: 11 | AI27: 0 | AJ27: 24 | AK27: 0 | AL27: 24 | AM27: 16 | AN27: 46 | AO27: 0.25806452 | AP27: 22 | AQ27: 4 | AR27: 38 | AS27: 0.095238095 | AT27: 28 | AU27: 5 | AV27: 33 | AW27: 0.13157895 | AX27: 26 | AY27: 7 | AZ27: 40 | BA27: 0.14893617 | BB27: 32 | BG27: 0 | BH27: 18 | BI27: 0 | BJ27: 18 | BK27: 103 | BL27: 562 | BM27: 0.13520831 | BN27: 694
A28: 159 | B28: Superga Own Bought | C28: 4 | D28: 9 | E28: 0.30769231 | F28: 34 | O28: 0 | P28: 6 | Q28: 0 | R28: 21 | S28: 0 | T28: 13 | U28: 0 | V28: 13 | AE28: 0 | AF28: 13 | AG28: 0 | AH28: 21 | AM28: 3 | AN28: 9 | AO28: 0.25 | AP28: 40 | AQ28: 2 | AR28: 9 | AS28: 0.18181818 | AT28: 48 | BK28: 9 | BL28: 59 | BM28: 0.12325175 | BN28: 177
A29: 164 | B29: Hotter | C29: 3 | D29: 38 | E29: 0.073170732 | F29: 80 | G29: 5 | H29: 38 | I29: 0.11627907 | J29: 78 | K29: 5 | L29: 33 | M29: 0.13157895 | N29: 74 | O29: 6 | P29: 24 | Q29: 0.2 | R29: 34 | S29: 7 | T29: 23 | U29: 0.23333333 | V29: 37 | W29: 6 | X29: 34 | Y29: 0.15 | Z29: 47 | AE29: 2 | AF29: 34 | AG29: 0.055555556 | AH29: 124 | AI29: 6 | AJ29: 52 | AK29: 0.10344828 | AL29: 46 | AM29: 9 | AN29: 63 | AO29: 0.125 | AP29: 50 | AQ29: 1 | AR29: 30 | AS29: 0.032258065 | AT29: 120 | AU29: 6 | AV29: 34 | AW29: 0.15 | AX29: 45 | AY29: 2 | AZ29: 19 | BA29: 0.095238095 | BB29: 86 | BK29: 58 | BL29: 422 | BM29: 0.12215517 | BN29: 821
